Workbook

Sheet 特性表
A1: 特性ID | B1: 特性名词 | C1: 特性描述 | D1: 实现细节 | E1: 分类(用于美术分类） | F1: Icon
A2: 1 | B2: 入场 | C2: 进入战场时触发 | D2: 被召唤入场，发射入场，移出后移入等都会触发 | E2: 扳机
A3: 2 | B3: 持续 | C3: 每个我方回合触发 | E3: 扳机 | J3: 4
A4: 3 | B4: 临时 | C4: 使用卡牌后消失，不进入弃牌堆，回合结束未使用也消失 | E4: 卡片属性 | F4: =_xlfn.DISPIMG("ID_546E2A9585AC483F88F79B1B0FABC91A",1) -> =DISPIMG("ID_546E2A9585AC483F88F79B1B0FABC91A",1)
A5: 4 | B5: 消耗 | C5: 移出本场战斗，不再抽到 | D5: 进入消耗堆，消耗堆不展示给玩家 | E5: 卡片属性 | F5: =_xlfn.DISPIMG("ID_41892C5987A24E9D8B5B91A5BF98D2B7",1) -> =DISPIMG("ID_41892C5987A24E9D8B5B91A5BF98D2B7",1)
A6: 5 | B6: 弹射 | C6: 默认状态，可以和任何实体碰撞 | E6: 单位（固有机制）
A7: 6 | B7: 穿透 | C7: 可穿透生物单位继续前进，但会被场景物件阻挡并反弹 | E7: 单位（固有机制） | F7: =_xlfn.DISPIMG("ID_5FE4F3319B1340A0A1AA8B69BA6A64D9",1) -> =DISPIMG("ID_5FE4F3319B1340A0A1AA8B69BA6A64D9",1)
A8: 7 | B8: 穿透{0} | C8: 最多可穿透{0}个单位 | E8: 单位（固有机制）
A9: 8 | B9: 场景穿透 | C9: 可穿透任何东西，永远是一条直线 | D9: 隐藏属性，不展示给玩家，会有宽度参数 | E9: 单位（固有机制） | F9: =_xlfn.DISPIMG("ID_379C38818A72462381D5A5FA72F2772D",1) -> =DISPIMG("ID_379C38818A72462381D5A5FA72F2772D",1)
A10: 9 | B10: 触发 | C10: 命中首个单位时触发效果 | E10: 扳机
A11: 10 | B11: 跟随 | C11: 打出时，跟随目标向打出方向位移 | D11: 位移力度根据不同情况配置 | E11: 单位（针对友方）
A12: 11 | B12: 停止 | C12: 首次发射停止后，产生XX效果 | D12: 最晚回合结束 | E12: 扳机
A13: 12 | B13: 圣盾 | C13: 抵挡一次伤害后消失，不可叠加 | D13: 抵挡伤害本质是将伤害变为0，仍算一次伤害，会触发伤害次数+1。本质为持续性效果，可被沉默等效果移除 | E13: 单位（针对友方） | F13: =_xlfn.DISPIMG("ID_C8C750FDD3534A9889D7EE7B2118CEA7",1) -> =DISPIMG("ID_C8C750FDD3534A9889D7EE7B2118CEA7",1)
A14: 13 | B14: 吸血 | C14: 造成伤害会为自身回复等量血量 | E14: 单位（针对敌方） | F14: =_xlfn.DISPIMG("ID_CA739DAFEB6E440EA04AC5D75AD83F16",1) -> =DISPIMG("ID_CA739DAFEB6E440EA04AC5D75AD83F16",1)
A15: 14 | B15: 剧毒 | C15: 造成伤害时直接消灭对方随从单位（非英雄） | D15: 攻击圣盾时不触发 | E15: 单位（针对敌方）
A16: 15 | B16: 回归 | C16: 满足特定条件，可以回到手牌 | D16: 重置为初始状态 | E16: 单位（固有机制）
A17: 16 | B17: 连发{0} | C17: 当前回合已经打出{0}张牌时生效该效果 | D17: 不算本身 | E17: 扳机
A18: 17 | B18: 激励 | C18: 在场时释放英雄技能时触发该效果 | E18: 扳机
A19: 18 | B19: 过载{0} | C19: 下回合英雄能量获取下降{0} | E19: 卡片属性
A20: 19 | B20: 任务 | C20: 完成任务后会获得奖励 | E20: 单位（无针对）
A21: 20 | B21: 招募 | C21: 从牌库中召唤一个特定条件的生物 | E21: 单位（无针对）
A22: 21 | B22: 复活 | C22: 首次死亡后以一点血量复活 | E22: 单位（固有机制）
A23: 22 | B23: 技能触发 | C23: 打出技能牌后触发效果，每回合只能触发一次 | E23: 扳机
A24: 23 | B24: 变形 | C24: 变形为一个指定对象 | D24: 不算死亡，等于替换为另一个单位，也不触发入场效果 | E24: 单位（无针对）
A25: 24 | B25: 发现 | C25: 从三张特定类型的卡中选择一张 | E25: 卡片属性
A26: 25 | B26: 沉默 | C26: 移除生物牌上的效果，包括所有增益和减益效果 | D26: 不影响当前血量，相当于一个初始进入场上的不带技能的版本 | E26: 单位（无针对）
A27: 26 | B27: 控制 | C27: 获得对方生物的控制权 | E27: 单位（针对敌方）
A28: 27 | B28: 移回手牌 | C28: 卡牌以初始状态移回手牌 | E28: 单位（无针对）
A29: 28 | B29: 移回牌库 | C29: 卡牌以初始状态移回抽牌库 | E29: 单位（无针对）
A30: 29 | B30: 丢弃卡牌 | C30: 选择特定卡牌丢入弃牌库 | D30: （可以是手牌或抽牌库） | E30: 卡片属性
A31: 30 | B31: 磨灭卡牌 | C31: 将特定卡牌移出本场战斗 | E31: 卡片属性
A32: 31 | B32: 技能免疫 | C32: 无视技能卡效果 | E32: 单位（针对友方）
A33: 32 | B33: 恐惧 | C33: 每回合首次开始移动时，施加一个随机方向的力 | D33: （移动方向变得随机） | E33: 单位（无针对）
A34: 33 | B34: 揭示{0} | C34: 随机从牌库中抽{0}张展示给双方 | D34: ，若没有其他操作，就洗回牌库。对该牌有其他操作，则打断洗回牌库 | E34: 卡片属性
A35: 34 | B35: 复制 | C35: 复制单位继承本体的特性和持续效果 | D35: 复制的卡牌同理，一模一样，只是多一个复制标签，表现也稍有不同，名字也改为XX的复制，额外的，复制有一个复制标签，用做某些逻辑判断。例如复制标签无法被复制 | E35: 卡片属性 | F35: =_xlfn.DISPIMG("ID_D40DEA4F8DA541AAB8904B6DA3B28089",1) -> =DISPIMG("ID_D40DEA4F8DA541AAB8904B6DA3B28089",1)
A36: 35 | B36: 亡语 | C36: 死亡时触发效果 | D36: 死亡是指血量归零或被消灭，放逐变形等不算 | E36: 单位（固有机制）
A37: 36 | B37: 保留 | C37: 回合结束时保留在手牌中 | D37: 不进弃牌堆 | E37: 卡片属性 | F37: =_xlfn.DISPIMG("ID_580FBEEFD99F44A1ADCF432152D5E945",1) -> =DISPIMG("ID_580FBEEFD99F44A1ADCF432152D5E945",1)
A38: 37 | B38: 铁壁{0} | C38: 每层抵消一次碰撞伤害 | D38: 非碰撞伤害无效，0攻碰撞不消除铁壁 | E38: 单位（针对友方）
A39: 38 | B39: 引导 | C39: 碰到的第一个单位停下时，目标向其位移 | E39: 单位（无针对）
A40: 39 | B40: 激怒 | C40: 向最近的敌方单位移动 | D40: 没有其他前缀限定时，即时生效 | E40: 单位（针对敌方）
...

Sheet check_info
A1: 一级ID | B1: 是否注释 | C1: 卡牌名 | D1: 技能效果
A2: 10010 | C2: 电吉他 和鸣 | D2: 回合结束时：我方每有一个在场单位，为我方英雄永久+{0}生命
A3: 10011 | C3: 纸巾 缠缠 | D3: 对同一敌方单位每多碰撞一次，伤害增加{0}%
A4: 10012 | C4: 摩托 赤狸 塞琳娜 | D4: 首次碰撞友方时，对其施加推力
A5: 10013 | C5: 雨伞 守心 布洛莉Brolly | D5: 碰撞友方时，为其添加圣盾
A6: 10014 | C6: 茶壶 灵愈 波西娅Potsia | D6: 碰撞友方时，为其恢复{0}点生命
A7: 10015 | C7: 留声机 回音 玛利亚 | D7: 回合结束时：对随机敌方单位造成{0}点伤害，每有{1}连击，伤害+{2}
A8: 10016 | C8: 电扇 彩虹 | D8: 在场时：我方打出的卡牌发射速度增加{0}%
A9: 10017 | C9: 电池 欧姆 | D9: 在场时：我方每获得{0}次连击数，额外获得{1}次连击
A10: 10018 | C10: 萨克斯 莉莉（Lily was here） | D10: 我方回合：每有我方单位离场时，我方英雄回复{0}点生命
A11: 10019 | C11: 电池 焦耳 | D11: 在场时：我方所有爆炸伤害增加{0}%
A12: 10020 | C12: 时钟 晨曦 | D12: 本局战斗：每打出一次，攻击力永久+{0}
A13: 10021 | C13: 自动铅笔 追忆 | D13: 在场时：每有一个我方单位入场，对随机敌方单位造成{0}伤害
A14: 10022 | B14: ## | C14: 橡皮 忘怀 | D14: 继承，我方回合，牺牲所有碰到的友方随从单位，获得其{0}%的当前属性
A15: 10023 | C15: 牙膏 露洁 爱丽儿（Ariel 小美人鱼） | D15: 回合结束时：分裂出{0}个分裂体
A16: 10024 | C16: 书 幻梦 仙蒂瑞拉 | D16: 回合结束时：牺牲英雄{0}点生命，抽{1}张牌
A17: 10025 | C17: 电池 伏特 | D17: 在场时：我方英雄获得连击数翻倍
A18: 10026 | C18: 功能饮料 牛红 | D18: 碰撞友方时：为该友方永久增加{0}点攻击力
A19: 10027 | B19: ## | C19: 牛奶 银河 | D19: 在场时：我方英雄获得吸血，每回合吸血上限为{1}
A20: 10028 | C20: 羽毛球 拉丽（英文就rally连续得分的意思） | D20: 打出时：有{0}%几率回到手牌，每次打出几率下降{1}%
A21: 10029 | C21: 姨妈巾 玫瑰 | D21: 回合结束时：根据我方牺牲总生命的{0}%，为我方英雄永久增加生命
A22: 10030 | C22: 军鼓 震声 | D22: 回合结束时：每有一个我方单位，对随机敌方单位造成一次{0}点伤害
A23: 10031 | C23: 注射器 针妮 佩妮（英文penny，联想小针） | D23: 每次碰撞我方：牺牲其{0}点生命，并为我方英雄永久加{1}生命
A24: 10032 | B24: ## | C24: 自行车 闪电 | D24: 首次碰撞随从单位时，施加一个较大的力
A25: 10033 | C25: 蜡烛 热泪 | D25: 在场时：每有一次爆炸，我方英雄生命+{0}
A26: 10034 | C26: 电钻 螺旋 | D26: 使碰撞到的敌方单位漏油
A27: 10035 | C27: 纯净水 浅浅 | D27: 无
A28: 10036 | C28: 纯净水 满满 | D28: 无
A29: 10037 | C29: 红汽水 浅浅 | D29: 无
A30: 10038 | B30: ## | C30: 红汽水 满满 | D30: 无
A31: 10039 | C31: 绿汽水 浅浅 | D31: 无
A32: 10040 | B32: ## | C32: 绿汽水 满满 | D32: 无
A33: 10041 | B33: ## | C33: 肥皂 滑滑 | D33: 降低自身摩擦力{0}%
A34: 10042 | C34: 刀 藏锋 | D34: 回合结束时：若连击数是单数，为我方英雄增加连击数*{0}%的攻击，若是双数，增加连击数{1}%的生命
A35: 10043 | C35: 刀 百炼 | D35: 每达成{0}连击，为生命百分比最低的我方回复{1}生命
A36: 10044 | C36: 煤油灯 流露 | D36: 首次碰撞后漏油，移动时留下油地面
A37: 10045 | C37: 盔甲 怀抱 | D37: 在场时：为所有我方分担{0}%的伤害，场上每有一个我方，自身忽略{1}%的伤害，最高忽略{2}%
A38: 10046 | C38: 啤酒瓶 破碎 | D38: 自身造成的连击数增加{0}%
A39: 10047 | B39: ## | C39: 暂时不做 | D39: 0
A40: 10048 | B40: ## | C40: 储蓄罐 珠珠 | D40: 0
...

Sheet HUDBUFF表
C1: 📁 | D1: \\sznas\fileshare\战略孵化部\FrozenCats工作室\美术素材\切图（交付）\I 图标Icon\C 词条图标
A2: 对应ID | B2: Buff/DeBuff名词 | C2: Icon/表现 | D2: 显示权重 | E2: 展示位置 | F2: 计数方式 | G2: 计数逻辑 | H2: 作用目标 | I2: 技能效果
A3: 13 | B3: 吸血 | D3: 4 | E3: HUD栏 | F3: 不计数 | G3: 通用buff，单位拥有吸血状态时显示
A4: 43 | B4: 点燃 | D4: 3 | E4: HUD栏 | F4: 计算层数(倒数) | G4: 通用buff，用于计算燃烧状态的剩余回合数，角标数字显示剩余回合数
A5: 44 | B5: 冻结 | D5: 3 | E5: HUD栏 | F5: 计算层数(倒数) | G5: 通用buff，用于计算冻结状态解除所需的剩余碰撞次数
A6: 45 | B6: 潮湿 | D6: 2 | E6: HUD栏 | F6: 不计数 | G6: 通用buff，被附加潮湿状态时显示
A7: 46 | B7: 漏油 | D7: 3 | E7: HUD栏 | F7: 计算层数(倒数) | G7: 通用buff，用于计算漏油状态剩余可生效漏油伤害的次数
A8: 52 | B8: 眩晕 | D8: 3 | E8: HUD栏 | F8: 计算层数(倒数) | G8: 通用buff，用于计算眩晕状态解除所需的剩余碰撞次数
A9: 20015 | B9: 英勇祝福 | D9: 5 | E9: UIBUFF栏 | F9: 计时 | G9: 技能buff，用于计算英勇祝福剩余时间，使用倒计时方式计数
A10: 20022 | B10: 蓄力 | D10: 5 | E10: UIBUFF栏 | F10: 计算层数(倒数) | G10: 技能buff，用于计算蓄力剩余的生效次数
A11: 61 | B11: 露娜BUFF | D11: 6 | E11: HUD栏 | F11: 计算层数(正数) | G11: 角色buff，仅用于统计英雄露娜 Hero_2 的技能累计的爆炸伤害层数 | H11: 角色自己 | I11: =单位卡分表!P55 -> 回合结束时：对随机敌方单位发射导弹造成{0}点爆炸伤害。我方每触发一次爆炸，范围永久增加{3}
A12: 30002 | B12: 能量 | D12: 6 | E12: HUD栏 | F12: 计算层数(倒数) | G12: 角色buff，仅用于单位电池伏特 Card_Creature_25 的技能生效所需的出牌数，计数累加，每{0}层归0一次并发动技能
A13: 20003 | B13: 禁止移动 | D13: 1 | E13: HUD栏 | F13: 计算层数 | G13: 通用buff，仅用于处于禁止位移的单位，例如当前版本的英雄维纳斯 Hero_4
A14: 30003 | B14: 后攻 | D14: 6 | E14: UIBUFF栏 | F14: 计算层数(倒数) | G14: 后攻专属buff，计数写死固定5层，每次加能量演出时减少1层，也可根据当前回合数计算
A15: 30004 | B15: 纸巾 缠缠 增伤标记 | D15: 3 | E15: HUD栏 | F15: 计算层数(正数) | G15: 角色附加在别的单位上的临时buff，仅用于计算纸巾 Creature_10011 的技能对碰撞到的单位附加的伤害增加层数，回合结束后消失。 | H15: 纸巾 撞击的目标 | I15: =单位卡分表!P12 -> 对同一敌方单位每多碰撞一次，伤害增加{0}%
A16: 62 | B16: 分裂体 | D16: 4 | E16: HUD栏 | F16: 不计数 | G16: 通用buff，所有分裂体附带此buff，变为本体后buff消失。 | H16: 分裂体自己
A17: 30005 | B17: 军鼓 触发次数统计 | D17: 6 | E17: HUD栏 | F17: 计算层数(正数) | G17: Creature_10030 角色buff，仅在我方回合显示，我方回合内，实时更新计算当前场上我方单位数量（回合结束时会触发的攻击次数） | H17: 角色自己 | I17: =单位卡分表!P31 -> 回合结束时：每有一个我方单位，对随机敌方单位造成一次{0}点伤害
A18: 30006 | B18: 刀 百炼 连击触发计数 | D18: 6 | E18: HUD栏 | F18: 计算层数(倒数) | G18: Creature_10043 角色buff，仅在我方回合显示，我方回合内，计算触发技能效果所需的剩余连击次数。（到0时触发并刷新） | H18: 角色自己 | I18: =单位卡分表!P44 -> 每达成{0}连击，为生命百分比最低的我方回复{1}生命
A19: 30007 | B19: 气球 飘舞 爆炸倒计时 | D19: 6 | E19: HUD栏 | F19: 计算层数(倒数) | G19: Creature_10051 角色buff，持续展示，计算剩余的蓄力结束回合数。（到0时爆炸） | H19: 角色自己 | I19: =单位卡分表!P52 -> 蓄力{0}回合后爆炸，造成{1}伤害
A20: 30008 | B20: 舰长 炸弹获得计数 | D20: 6 | E20: HUD栏 | F20: 计算层数(倒数) | G20: Hero_10000 角色buff，持续展示，计算获得炸弹卡牌所需的剩余出牌张数。（到0时获得并刷新） | H20: 角色自己 | I20: =单位卡分表!P53 -> 每打出{0}张卡，获得一张炸蛋
A22: 63 | B22: 吞噬中 | D22: 4 | E22: HUD栏 | F22: 计算层数(正数) | G22: 通用buff，角色具有吞噬特性，且当前已有吞噬单位时，显示此Icon。 | H22: 角色自己 | I22: 0为未吞噬，非0为已吞噬，未吞噬Icon为632
A23: 30009 | B23: 电吉他 标记数 | D23: 6 | E23: HUD栏 | F23: 计算层数(正数) | G23: Creature_10010 角色buff，仅在我方回合显示，我方回合内，实时计算在场我方单位数量，回合结束触发技能时消失。 | H23: 角色自己 | I23: =单位卡分表!P11 -> 回合结束时：我方每有一个在场单位，为我方英雄永久+{0}生命
A24: 34 | B24: 复制体 | D24: 2 | E24: HUD栏 | F24: 不计数 | G24: 通用buff，角色是复制体。 | H24: 复制体自己

Sheet 单位卡分表
A1: 卡牌ID | B1: 卡牌名 | C1: 卡牌类型 | D1: 选项类型 | E1: 射击类型 | F1: 职业 | G1: 费用 | H1: 稀有度 | I1: 获取方式类型 | J1: AI目标规划 | K1: 瞄准线类型 | L1: 牌序规划标签 | M1: 等级上限 | N1: 英雄卡ID | O1: 版本过滤 | P1: 卡牌效果 | Q1: 效果备注 | R1: 卡牌效果2级 | S1: 2级效果备注 | T1: 卡牌效果3级 | U1: 3级效果备注 | V1: 流派归类（后续用作职业划分） | W1: 特性列表（特性ID） | Z1: Demo版本 技能表现 | AA1: 特效已加入？ | AB1: Demo版本 包装 | AC1: 一测版本 包装 | AE1: 失效次数 | AF1: 失效参数 | AG1: 技能类型 | AL1: 是否需要物理模拟
A2: 10001 | B2: 模版生物1 | C2: 1 | F2: 无 | G2: 1 | J2: 常规碰撞 | K2: 1 | L2: 5 | M2: 3 | O2: 0 | P2: 无 | Q2: 无 | AB2: 电视
A3: 10002 | B3: 模版生物2 | C3: 1 | F3: 无 | G3: 2 | J3: 常规碰撞 | K3: 1 | L3: 5 | M3: 3 | O3: 0 | P3: 无 | Q3: 无 | AB3: 水壶
A4: 10003 | B4: 模版生物3 | C4: 1 | F4: 无 | G4: 3 | J4: 常规碰撞 | K4: 1 | L4: 5 | M4: 3 | O4: 0 | P4: 无 | Q4: 无 | AB4: 剪刀
A5: 10004 | B5: 模版生物4 | C5: 1 | F5: 无 | G5: 4 | J5: 常规碰撞 | K5: 1 | L5: 5 | M5: 3 | O5: 0 | P5: 无 | Q5: 无 | AB5: 牙膏
A6: 10005 | B6: 模版生物5 | C6: 1 | F6: 无 | G6: 5 | J6: 常规碰撞 | K6: 1 | L6: 5 | M6: 3 | O6: 0 | P6: 无 | Q6: 无 | AB6: 鼠标
A7: 10006 | B7: 模版生物6 | C7: 1 | F7: 无 | G7: 6 | J7: 常规碰撞 | K7: 1 | L7: 5 | M7: 3 | O7: 0 | P7: 无 | Q7: 无
A8: 10007 | B8: 模版生物7 | C8: 1 | F8: 无 | G8: 7 | J8: 常规碰撞 | K8: 1 | L8: 5 | M8: 3 | O8: 0 | P8: 无 | Q8: 无
A9: 10008 | B9: 模版生物8 | C9: 1 | F9: 无 | G9: 8 | J9: 常规碰撞 | K9: 1 | L9: 5 | M9: 3 | O9: 0 | P9: 无 | Q9: 无
A10: 10009 | B10: 模版生物9 | C10: 1 | F10: 无 | G10: 9 | J10: 常规碰撞 | K10: 1 | L10: 5 | M10: 3 | O10: 0 | P10: 无 | Q10: 无
A11: 10010 | B11: 电吉他 和鸣 | C11: 1 | D11: 1 | E11: 1 | F11: 4 | G11: 5 | H11: 3 | I11: 0 | J11: 更多我方单位 | K11: 1 | L11: 5 | M11: 3 | O11: 1 | P11: 回合结束时：我方每有一个在场单位，为我方英雄永久+{0}生命 | Q11: 注意统一以造成的实际伤害论，打到1血单位，算造成1伤害 | V11: 1，5 | Z11: 每次触发对随机敌方造成伤害效果时，在受伤单位球处生成一个跟随球位移的攻击特效，并跳出伤害数字，特效播放完成后销毁 📦Effect_Creature15_Hit | AA11: 0 | AB11: 蜡烛（火苗） | AC11: 电吉他 | AG11: CollisionCauseDamage2RandomEnemy | AJ11: 2 | AL11: 1 | AM11: 1
A12: 10011 | B12: 纸巾 缠缠 | C12: 6 | D12: 1 | E12: 1 | F12: 3 | G12: 5 | H12: 3 | I12: 0 | J12: 常规碰撞（多次碰一个人加分） | K12: 1 | L12: 5 | M12: 3 | O12: 1 | P12: 对同一敌方单位每多碰撞一次，伤害增加{0}% | Q12: 可以加上标记，伤害向上取整，先加后乘。每回合最多触发{1}次 | V12: 0 | Z12: 每次碰撞敌方触发攻击伤害增加效果时，在该敌方球body位置播放1次📦Effect_Creature11_Hit特效并跟随敌方球进行移动 | AB12: 纸卷（纠缠） | AC12: 纸巾 | AG12: CauseDamageByCollisionTimes | AJ12: 2 | AL12: 1 | AM12: 1
A13: 10012 | B13: 摩托 赤狸 塞琳娜 | C13: 6 | D13: 1 | E13: 1 | F13: 4 | G13: 5 | H13: 3 | I13: 1 | J13: 我方英雄 | K13: 1 | L13: 7 | M13: 3 | O13: 1 | P13: 首次碰撞友方时，对其施加推力 | Q13: 隐藏推力{0} | V13: 3，4，5 | Z13: 触发该效果时，在碰撞位置播放一个曝气特效，播放完成后销毁 📦Effect_Creature13_Crash，该特效不跟随单位球移动 | AB13: 电吉他（音爆） | AC13: 摩托 | AE13: Times | AF13: 1 | AG13: CollisionHeroAddForceOnce | AJ13: 2 | AK13: 1 | AL13: 1 | AM13: 1
A14: 10013 | B14: 雨伞 守心 布洛莉Brolly | C14: 6 | D14: 1 | E14: 1 | F14: 2 | G14: 4 | H14: 3 | I14: 0 | J14: 更多我方单位 | K14: 1 | L14: 6 | M14: 3 | O14: 1 | P14: 碰撞友方时，为其添加圣盾 | Q14: 隐藏触发上限{0}次 | W14: 12 | Z14: （通用效果——圣盾： 被附加圣盾效果的单位，在该单位球处生成并播放📦Effect_ShieldUP，该特效跟随单位球body缩放，该特效跟随单位球移动 失去圣盾效果的单位，销毁该单位的📦Effect_ShieldUP 特效，并同时在该单位球Body处播放1次📦Effect_ShieldBreak 特效，该特效不跟随单位球移动和缩放） | AB14: 电风扇（吹风） | AC14: 雨伞 | AG14: AddShieldToCollisionTeammate | AK14: 1 | AL14: 1 | AM14: 1
A15: 10014 | B15: 茶壶 灵愈 波西娅Potsia | C15: 6 | D15: 1 | E15: 1 | F15: 2 | G15: 5 | H15: 3 | I15: 0 | J15: 我方高价值单位 | K15: 1 | L15: 6 | M15: 3 | O15: 1 | P15: 碰撞友方时，为其恢复{0}点生命 | Q15: 敌方回合也生效。隐藏触发上限{1}次 | AB15: 书（多张） | AC15: 茶壶 | AG15: CollisionTeammateRecoverHp | AL15: 1 | AM15: 1
A16: 10015 | B16: 留声机 回音 玛利亚 | C16: 1 | D16: 1 | E16: 1 | F16: 3 | G16: 5 | H16: 3 | I16: 0 | J16: 常规碰撞 | K16: 1 | L16: 5 | M16: 3 | O16: 1 | P16: 回合结束时：对随机敌方单位造成{0}点伤害，每有{1}连击，伤害+{2} | V16: 0 | W16: 53 | Z16: 该单位始终循环附带通用攻击光环特效 📦Effect_SustainableBuff_PowerLoop 触发回合结束的造成伤害效果时，在目标单位处播放攻击特效 📦Effect_Creature12_Hit，该特效跟随单位球移动 | AB16: 留声机（留声） | AC16: 留声机 | AE16: Times | AF16: 1 | AG16: CausePercentAttackDamageByComboCounts | AJ16: 2 | AL16: 1 | AM16: 1
A17: 10016 | B17: 电扇 彩虹 | C17: 1 | D17: 1 | E17: 1 | F17: 1 | G17: 5 | H17: 2 | I17: 0 | J17: 常规碰撞 | K17: 1 | L17: 2 | M17: 3 | O17: 1 | P17: 在场时：我方打出的卡牌发射速度增加{0}% | Q17: 可叠加，所有百分比加成，先加后乘，AddShootCardSpeedPercent | V17: 0 | Z17: 该单位始终循环附带通用增益光环特效 📦Effect_SustainableBuff_Loop | AB17: 牛奶（大补） | AC17: 电风扇（吹风） | AG17: CreatureAddShootCardSpeed | AJ17: 2 | AL17: 1 | AM17: 1
A18: 10017 | B18: 电池 欧姆 | C18: 1 | D18: 1 | E18: 1 | F18: 1 | G18: 7 | H18: 4 | I18: 1 | J18: 常规碰撞 | K18: 1 | L18: 2 | M18: 3 | O18: 1 | P18: 在场时：我方每获得{0}次连击数，额外获得{1}次连击 | Q18: 多个欧姆不叠加 | V18: 0 | W18: 53 | Z18: 该单位始终循环附带通用增益光环特效 📦Effect_SustainableBuff_Loop 生成能量时，从本体单位处生成一个📦Effect_EnergyTail飞至对应方能量条处后消失 | AC18: 电池1 | AG18: AddEnergyForHeroAtRoundOver | AJ18: 2 | AL18: 1
A19: 10018 | B19: 萨克斯 莉莉（Lily was here） | C19: 1 | D19: 1 | E19: 1 | F19: 1 | G19: 6 | H19: 3 | I19: 0 | J19: 常规碰撞（击杀权重大大增加） | K19: 1 | L19: 2.5 | M19: 3 | O19: 1 | P19: 我方回合：每有我方单位离场时，我方英雄回复{0}点生命 | Q19: （死亡，被吞噬，雇佣兵都算），被吞噬后，被吞噬单位死亡，只算一次离场（因为吞噬已经算离场了） | V19: 0 | Z19: 该单位始终循环附带通用攻击光环特效 📦Effect_SustainableBuff_PowerLoop 每次触发对随机敌方造成伤害的效果时，从本体单位位置生成一个📦Effect_Creature18_Fly，0.3s内飞至随机攻击的单位处，飞至终点时，在目标单位球处播放1次📦Effect_Creature15_Hit并跟随球移动 | AC19: 乐器娘2（萨克斯） | AG19: CauseDamageWhenKillEnemy | AJ19: 2 | AL19: 1 | AM19: 1
A20: 10019 | B20: 电池 焦耳 | C20: 1 | D20: 1 | E20: 1 | F20: 1 | G20: 5 | H20: 3 | I20: 1 | J20: 常规碰撞 | K20: 1 | L20: 2 | M20: 3 | O20: 1 | P20: 在场时：我方所有爆炸伤害增加{0}% | V20: 0 | W20: 61 | Z20: 该单位始终循环附带通用增益光环特效 📦Effect_SustainableBuff_Loop 生成能量时，从本体单位处生成一个📦Effect_EnergyTail飞至对应方能量条处后消失 | AC20: 电池2 | AG20: AddEnergyWhenKillEnemy | AJ20: 2 | AL20: 1
A21: 10020 | B21: 时钟 晨曦 | C21: 6 | D21: 1 | E21: 1 | F21: 3 | G21: 5 | H21: 3 | I21: 0 | J21: 常规碰撞 | K21: 1 | L21: 5 | M21: 3 | O21: 1 | P21: 本局战斗：每打出一次，攻击力永久+{0} | V21: 2 | Z21: 打出该单位后，在该单位body处生成一个📦Effect_AttackUp特效播放1次，并跟随该单位球进行移动 （通用特效：当前攻击力大于原始攻击力的单位，body处始终循环播放📦Effect_AttackUp_Loop特效，并跟随单位球移动，直到不满足条件或死亡） | AC21: 时钟（时间） | AE21: Times | AF21: 1 | AG21: AddAttackWhenShootCard | AJ21: 2 | AK21: 1 | AL21: 1 | AM21: 1
A22: 10021 | B22: 自动铅笔 追忆 | C22: 1 | D22: 1 | E22: 1 | F22: 1 | G22: 7 | H22: 3 | I22: 0 | J22: 常规碰撞 | K22: 1 | L22: 2 | M22: 3 | O22: 1 | P22: 在场时：每有一个我方单位入场，对随机敌方单位造成{0}伤害 | V22: 1 | Z22: 该单位始终循环附带通用攻击光环特效 📦Effect_SustainableBuff_PowerLoop 每次触发对随机敌方造成伤害的效果时，在本体单位球处生成并播放1次📦Effect_Creature21_Line，播放特效后0.1s再触发实际的法术效果，该特效需要计算目标单位球与本体单位球的角度并旋转Y值 | AC22: 铅笔 | AG22: ShootCardCauseDamageWhenAlive | AJ22: 2 | AK22: 1 | AL22: 1 | AM22: 1
A23: 10022 | B23: 橡皮 忘怀 | C23: 1 | D23: 1 | E23: 1 | F23: 4 | G23: 4 | H23: 3 | I23: 0 | J23: 更多我方随从单位 | K23: 1 | L23: 6.7 | M23: 3 | O23: 0 | P23: 继承，我方回合，牺牲所有碰到的友方随从单位，获得其{0}%的当前属性 | Q23: 改为继承特性 | V23: 1 | W23: 57 | Z23: 触发牺牲单位效果时，走常规击杀单位的流程，且在被击杀的单位处播放1次📦Effect_Creature22_Hit，该特效不跟随尸体移动 | AC23: 橡皮 | AG23: SacrificeCollisionCreature | AJ23: 2 | AK23: 1 | AL23: 1 | AM23: 1
A24: 10023 | B24: 牙膏 露洁 爱丽儿（Ariel 小美人鱼） | C24: 1 | D24: 1 | E24: 1 | F24: 1 | G24: 4 | H24: 4 | I24: 0 | J24: 常规碰撞 | K24: 1 | L24: 5 | M24: 3 | O24: 1 | P24: 回合结束时：分裂出{0}个分裂体 | V24: 1 | W24: 62 | Z24: （通用特效：召唤单位和生成物，在要召唤单位的位置播放📦Effect_Summon） | AC24: 牙膏 | AG24: SplitSelf | AJ24: 2 | AL24: 1 | AM24: 1
A25: 10024 | B25: 书 幻梦 仙蒂瑞拉 | C25: 1 | D25: 1 | E25: 1 | F25: 1 | G25: 6 | H25: 3 | I25: 1 | J25: 常规碰撞 | K25: 1 | L25: 5 | M25: 3 | O25: 1 | P25: 回合结束时：牺牲英雄{0}点生命，抽{1}张牌 | Q25: 在抽牌之前触发 | V25: 2 | Z25: 该单位始终循环附带通用增益光环特效 📦Effect_SustainableBuff_Loop 触发效果时，在对应英雄球位置播放1次📦Effect_LossLife_Flash，该特效跟随球移动 | AC25: 书 | AG25: GetMoreHandCard | AJ25: 2（待确认，牌堆无牌可抽也扣血） | AK25: 1 | AL25: 1 | AM25: 1
A26: 10025 | B26: 电池 伏特 | C26: 1 | D26: 1 | E26: 1 | F26: 1 | G26: 7 | H26: 3 | I26: 1 | J26: 常规碰撞 | K26: 1 | L26: 2 | M26: 3 | O26: 1 | P26: 在场时：我方英雄获得连击数翻倍 | Q26: 多个同时在场没用，都只是翻倍 | V26: 2 | W26: 53 | Z26: 该单位始终循环附带通用增益光环特效 📦Effect_SustainableBuff_Loop 生成能量时，从本体单位处生成一个📦Effect_EnergyTail飞至对应方能量条处后消失 | AC26: 电池3 | AG26: AddEnergyWhenShootCard | AJ26: 2 | AL26: 1
A27: 10026 | B27: 功能饮料 牛红 | C27: 6 | D27: 1 | E27: 1 | F27: 2 | G27: 5 | H27: 3 | I27: 0 | J27: 我方英雄 | K27: 1 | L27: 6 | M27: 3 | O27: 1 | P27: 碰撞友方时：为该友方永久增加{0}点攻击力 | Q27: 注意AI碰大蛇的处理。最多触发{1}次 | V27: 5 | Z27: 该单位始终循环附带通用增益光环特效 📦Effect_SustainableBuff_Loop 每次触发为英雄提升攻击力效果时，在对应英雄单位body处生成一个📦Effect_AttackUp特效播放1次，并跟随该单位球进行移动 （通用特效：当前攻击力大于原始攻击力的单位，body处始终循环播放📦Effect_AttackUp_Loop特效，并跟随单位球移动，直到不满足条件或死亡） | AC27: 爆米花 | AG27: CollisionHeroAddAttack | AJ27: 2 | AL27: 1 | AM27: 1
A28: 10027 | B28: 牛奶 银河 | C28: 1 | D28: 1 | E28: 1 | F28: 1 | G28: 5 | H28: 4 | I28: 0 | J28: 常规碰撞 | K28: 1 | L28: 2 | M28: 3 | O28: 0 | P28: 在场时：我方英雄获得吸血，每回合吸血上限为{1} | Q28: 吸血buff ID xxx。吸血特性{0} | V28: 3,5 | W28: 13 | Z28: 该单位始终循环附带通用增益光环特效 📦Effect_SustainableBuff_Loop （通用效果：吸血，触发时从被吸血的单位球处生成1个📦Effect_Lifesteal_Fly，飞至发动吸血的单位处后消失） （通用效果：回复血量，单位回复生命时，无论是否满血，都在该单位球处生成1个📦Effect_Health_Hit，跟随单位球移动，播放完成后消失） | AC28: 牛奶 | AG28: AddBuffToHeroWhenAlive | AJ28: 2 | AL28: 1 | AM28: 1
A29: 10028 | B29: 羽毛球 拉丽（英文就rally连续得分的意思） | C29: 6 | D29: 1 | E29: 1 | F29: 3 | G29: 5 | H29: 2 | I29: 0 | J29: 常规碰撞 | K29: 1 | L29: 5 | M29: 3 | O29: 1 | P29: 打出时：有{0}%几率回到手牌，每次打出几率下降{1}% | V29: 1，2 | Z29: 需要Spine配合 | AC29: 羽毛球 | AG29: RebackHandCard | AJ29: 2 | AK29: 1 | AL29: 1 | AM29: 1
A30: 10029 | B30: 姨妈巾 玫瑰 | C30: 1 | D30: 1 | E30: 1 | F30: 3 | G30: 5 | H30: 4 | I30: 0 | J30: 常规碰撞 | K30: 1 | L30: 5 | M30: 3 | O30: 1 | P30: 回合结束时：根据我方牺牲总生命的{0}%，为我方英雄永久增加生命 | Q30: 当前生命值。我方回合我方损失 | V30: 0 | Z30: 打出时，从被吸取生命的英雄Body位置生成飞行道具📦Effect_Creature29_Fly，飞行1s飞至姨妈巾处，飞至姨妈巾处后在姨妈巾的Body位置播放一次📦Effect_Creature29_Hit，该特效跟随单位球移动 特效部分仅作为表现存在，实际卡牌效果在打出瞬间立即生效 | AC30: 姨妈巾 | AE30: Times | AF30: 1 | AG30: AuntTowel | AJ30: 2 | AL30: 1 | AM30: 1
A31: 10030 | B31: 军鼓 震声 | C31: 1 | D31: 1 | E31: 1 | F31: 3 | G31: 7 | H31: 3 | I31: 1 | J31: 常规碰撞 | K31: 1 | L31: 5 | M31: 3 | O31: 1 | P31: 回合结束时：每有一个我方单位，对随机敌方单位造成一次{0}点伤害 | V31: 1 | Z31: 触发该效果时，每次对敌方造成伤害，在对应受伤害的单位球处生成并播放1次📦Effect_Creature30_Hit，造成伤害间隔为0.1s | AC31: 鼠标 | AG31: CauseDamageAccordOurActorNumAtRoundOver | AJ31: 2 | AL31: 1 | AM31: 1
A32: 10031 | B32: 注射器 针妮 佩妮（英文penny，联想小针） | C32: 6 | D32: 1 | E32: 1 | F32: 3 | G32: 7 | H32: 3 | I32: 0 | J32: 常规碰撞 | K32: 1 | L32: 6 | M32: 3 | O32: 1 | P32: 每次碰撞我方：牺牲其{0}点生命，并为我方英雄永久加{1}生命 | Q32: 可以吸死 | V32: 3，5 | Z32: 打出时，从所有被吸取生命的单位Body位置生成飞行道具📦Effect_Creature29_Fly，飞行1s飞至姨妈巾处，飞至姨妈巾处后在姨妈巾的Body位置播放一次📦Effect_Creature29_Hit，该特效跟随单位球移动 特效部分仅作为表现存在，实际卡牌效果在打出瞬间立即生效 | AB32: 76 | AC32: 注射器 | AE32: Times | AF32: 1 | AG32: Syringe | AJ32: 2 | AL32: 1 | AM32: 1
A33: 10032 | B33: 自行车 闪电 | C33: 6 | D33: 1 | E33: 1 | F33: 3 | G33: 4 | H33: 1 | I33: 0 | J33: 高价值敌方单位 | K33: 1 | L33: 5 | M33: 3 | O33: 0 | P33: 首次碰撞随从单位时，施加一个较大的力 | Q33: 敌我都行，隐藏参数力大小{0} | V33: 0 | Z33: 触发该效果时，在碰撞位置播放一个曝气特效，播放完成后销毁 📦Effect_Creature13_Crash | AC33: 自行车 | AE33: Times | AF33: 1 | AG33: CollisionRetinueAddForceOnce | AJ33: 2 | AL33: 1 | AM33: 1
A34: 10033 | B34: 蜡烛 热泪 | C34: 1 | D34: 1 | E34: 1 | F34: 3 | G34: 3 | H34: 3 | I34: 0 | J34: 高价值敌方单位 | K34: 1 | L34: 2 | M34: 3 | O34: 1 | P34: 在场时：每有一次爆炸，我方英雄生命+{0} | V34: 0 | W34: 61 | AC34: 蜡烛 | AE34: Times | AF34: 1 | AG34: FireSelfButImmunityDamage | AJ34: 2 | AL34: 1 | AM34: 1
A35: 10034 | B35: 电钻 螺旋 | C35: 6 | D35: 1 | E35: 1 | F35: 3 | G35: 5 | H35: 4 | I35: 0 | J35: 高价值敌方单位 | K35: 1 | L35: 6 | M35: 3 | O35: 1 | P35: 使碰撞到的敌方单位漏油 | Q35: 漏油特性ID{0}，隐藏敌方漏油格数上限{1}，漏油上限指，被碰撞到的敌方运动后，最多在{1}个地面留下漏油单元格 | V35: 0 | W35: 46 | Z35: 该单位每次碰撞敌方，仅触发流血时，在碰撞位置生成一个📦Effect_Creature34_Hit，播放一次，不跟随球移动 | AC35: 剪刀 | AG35: CollisionAddBuffToOthers | AJ35: 2 | AL35: 1 | AM35: 1
A36: 10035 | B36: 纯净水 浅浅 | C36: 1 | D36: 1 | E36: 1 | F36: 3 | G36: 2 | H36: 1 | I36: 0 | J36: 高价值敌方单位 | K36: 1 | L36: 5 | M36: 3 | O36: 1 | P36: 无 | Q36: 凑数属性怪，白水瓶娘浅，均衡攻血 | V36: 0 | AC36: 白水瓶娘浅 | AL36: 1 | AM36: 1
A37: 10036 | B37: 纯净水 满满 | C37: 1 | D37: 1 | E37: 1 | F37: 3 | G37: 4 | H37: 1 | I37: 0 | J37: 高价值敌方单位 | K37: 1 | L37: 5 | M37: 3 | O37: 1 | P37: 无 | Q37: 凑数属性怪，白水瓶娘满，均衡攻血 | V37: 0 | AC37: 白水瓶娘满 | AL37: 1 | AM37: 1
A38: 10037 | B38: 红汽水 浅浅 | C38: 1 | D38: 1 | E38: 1 | F38: 3 | G38: 3 | H38: 1 | I38: 0 | J38: 高价值敌方单位 | K38: 1 | L38: 5 | M38: 3 | O38: 1 | P38: 无 | Q38: 凑数属性怪，红水瓶娘浅，高攻低血 | V38: 0 | AC38: 红水瓶娘浅 | AL38: 1 | AM38: 1
A39: 10038 | B39: 红汽水 满满 | C39: 1 | D39: 1 | E39: 1 | F39: 3 | G39: 5 | H39: 1 | I39: 0 | J39: 高价值敌方单位 | K39: 1 | L39: 5 | M39: 3 | O39: 0 | P39: 无 | Q39: 凑数属性怪，红水瓶娘满，高攻低血 | V39: 0 | AC39: 红水瓶娘满 | AL39: 1 | AM39: 1
A40: 10039 | B40: 绿汽水 浅浅 | C40: 1 | D40: 1 | E40: 1 | F40: 3 | G40: 4 | H40: 1 | I40: 0 | J40: 高价值敌方单位 | K40: 1 | L40: 5 | M40: 3 | O40: 1 | P40: 无 | Q40: 凑数属性怪，绿水瓶娘浅，低攻高血 | V40: 0 | AC40: 绿水瓶娘浅 | AL40: 1 | AM40: 1
...

Sheet 技能卡分表
A1: 卡牌ID | B1: 名称 | C1: 卡牌类型 | D1: 选项类型 | E1: 射击类型 | F1: 职业 | G1: 费用 | H1: 稀有度 | I1: 获取方式类型 | J1: AI目标规划 | K1: 瞄准线类型 | L1: 牌序规划标签 | M1: 等级上限 | N1: 废弃 | O1: 不放入商店 | P1: 卡牌效果 | Q1: 效果备注 | R1: 卡牌效果2级 | S1: 2级效果备注 | T1: 卡牌效果3级 | U1: 3级效果备注 | V1: 流派归类（后续用作职业划分） | W1: 特性列表（特性ID） | Z1: 引用交互物列表（交互物ID） | AB1: 技能表现 | AC1: 额外备注 | AD1: 特效已加入？ | AE1: 失效次数 | AF1: 失效参数 | AG1: 技能类型 | AJ1: 是否需要物理模拟
A2: 20001 | B2: 模版法术1 | C2: 2 | D2: 1 | F2: 无 | G2: 1 | J2: 高价值敌方单位 | K2: 3 | L2: 5 | N2: 1 | O2: 1 | P2: 命中首个敌方单位时，对其造成X点伤害 | Q2: 无
A3: 20002 | B3: 模版法术2 | C3: 2 | D3: 1 | F3: 无 | G3: 2 | J3: 高价值敌方单位 | K3: 3 | L3: 5 | N3: 1 | O3: 1 | P3: 命中首个敌方单位时，对其造成X点伤害 | Q3: 无
A4: 20003 | B4: 模版法术3 | C4: 2 | D4: 1 | F4: 无 | G4: 3 | J4: 高价值敌方单位 | K4: 3 | L4: 5 | N4: 1 | O4: 1 | P4: 命中首个敌方单位时，对其造成X点伤害 | Q4: 无
A5: 20004 | B5: 模版法术4 | C5: 2 | D5: 1 | F5: 无 | G5: 4 | J5: 高价值敌方单位 | K5: 3 | L5: 5 | N5: 1 | O5: 1 | P5: 命中首个敌方单位时，对其造成X点伤害 | Q5: 无
A6: 20005 | B6: 模版法术5 | C6: 2 | D6: 1 | F6: 无 | G6: 5 | J6: 高价值敌方单位 | K6: 3 | L6: 5 | N6: 1 | O6: 1 | P6: 命中首个敌方单位时，对其造成X点伤害 | Q6: 无
A7: 20006 | B7: 模版法术6 | C7: 2 | D7: 1 | F7: 无 | G7: 6 | J7: 高价值敌方单位 | K7: 3 | L7: 5 | N7: 1 | O7: 1 | P7: 命中首个敌方单位时，对其造成X点伤害 | Q7: 无
A8: 20007 | B8: 模版法术7 | C8: 2 | D8: 1 | F8: 无 | G8: 7 | J8: 高价值敌方单位 | K8: 3 | L8: 5 | N8: 1 | O8: 1 | P8: 命中首个敌方单位时，对其造成X点伤害 | Q8: 无
A9: 20008 | B9: 模版法术8 | C9: 2 | D9: 1 | F9: 无 | G9: 8 | J9: 高价值敌方单位 | K9: 3 | L9: 5 | N9: 1 | O9: 1 | P9: 命中首个敌方单位时，对其造成X点伤害 | Q9: 无
A10: 20009 | B10: 模版法术9 | C10: 2 | D10: 1 | F10: 无 | G10: 9 | J10: 高价值敌方单位 | K10: 3 | L10: 5 | N10: 1 | O10: 1 | P10: 命中首个敌方单位时，对其造成X点伤害 | Q10: 无
A11: 20010 | B11: 切分 | C11: 2 | D11: 2 | E11: 1 | F11: 4 | G11: 5 | H11: 4 | I11: 3 | J11: 更多我方随从单位 | K11: 7 | L11: 6.3 | M11: 1 | P11: 场景穿透，将经过的我方非复制随从单位切成两个较小的复制单位，属性为原单位的{2}% | Q11: 属性百分比可配，向上取整，隐藏参数，体积减小{0}%，质量减少{1}% | V11: 0 | W11: 8 | X11: 34 | AB11: 发动法术后，从发射点位置生成并播放1次📦Effect_Magic10_Shoot，生成时的旋转角度与操作发射角度相同，触发效果时，在每个被击中的单位球Body处生成并播放1次📦Effect_Magic10_Hit | AE11: Times | AF11: 1 | AG11: SplitCollisionCreature | AJ11: 0 | AK11: 1
A12: 20011 | B12: 魅惑 | C12: 2 | D12: 2 | E12: 1 | F12: 4 | G12: 4 | H12: 4 | I12: 3 | J12: 高价值我方单位 | K12: 6 | L12: 7.1 | M12: 3 | P12: 指定战场任意位置，敌方英雄向该位置位移 | Q12: 隐藏参数位移力度{0}，不能移动的英雄不生效 | R12: 指定战场任意位置，敌方英雄向该位置位移，位移力量更大 | S12: 隐藏参数位移力度{0}，不能移动的英雄不生效 | T12: 指定战场任意位置，敌方英雄向该位置位移，位移力量最大 | U12: 隐藏参数位移力度{0}，不能移动的英雄不生效 | V12: 0 | W12: 41 | AB12: 发动法术后，在指定的战场位置生成一个📦Effect_Magic11，英雄在延迟0.4s后向目标方向位移 | AE12: Times | AF12: 1 | AG12: CharmHero | AJ12: 0 | AK12: 1
A13: 20012 | B13: 弹射锯片 | C13: 2 | D13: 2 | E13: 1 | F13: 3 | G13: 4 | H13: 5 | I13: 0 | J13: 更多敌方单位 （飞行路径敌方伤害价值取最高） | K13: 2 | L13: 5 | M13: 3 | P13: 穿透，造成{0}伤害，每穿透一个单位伤害增加{1}% | Q13: 计算友方单位，先加后乘，隐藏参数最小伤害间隔{2}秒 | V13: 1 | W13: 6 | AB13: 生成一个飞行道具特效按照技能规则进行移动 📦Effect_Magic12_Fly 对造成伤害的单位，球位置处，播放一个受击特效 📦Effect_Magic12_Hit | AC13: 无敌风火轮 | AE13: Times | AF13: 1 | AG13: CollisionCauseDamage | AJ13: 1 | AK13: 1
A14: 20013 | B14: 自制手雷 | C14: 2 | D14: 2 | E14: 1 | F14: 3 | G14: 3 | H14: 3 | I14: 0 | J14: 高价值敌方单位 （所有单位圆形范围敌方伤害价值取最高） | K14: 4 | L14: 5 | M14: 3 | P14: 碰到首个敌方时，对范围内的敌方造成{0}伤害 | Q14: 隐藏参数范围大小{1}，隐藏参数中心点向四周的推力{2} | V14: 0 | AB14: 生成一个飞行道具特效按照技能规则进行移动 📦Effect_Magic13_Fly 在接触点位置生成爆炸特效，该特效跟随范围数值缩放 📦Effect_Magic13_Hit | AC14: 火球术 | AE14: Times | AF14: 1 | AG14: CollisionCauseRangeDamageOnce | AJ14: 1 | AK14: 1
A15: 20014 | B15: 见证我！ | C15: 2 | D15: 2 | E15: 1 | F15: 4 | G15: 3 | H15: 2 | I15: 0 | J15: 无目标 | K15: 5 | L15: 5 | M15: 3 | P15: 杀死我方生命最低的随从，对周围敌方造成{0}点伤害 | Q15: 隐藏参数范围大小{1}，推力参数{2}，如果有多个血量相同的单位例如牙膏，则都爆炸，多个爆炸做个小延时。拖出去时提示一下哪些单位会爆炸 | V15: 1 | W15: 36 | AB15: 以0.1s为间隔，顺序在爆炸球坐标处播放爆炸特效，该特效跟随范围数值缩放 📦Effect_Magic14 | AC15: 自爆 | AE15: Times | AF15: 1 | AG15: SelfDestructCauseRangeDamage | AJ15: 0 | AK15: 1
A16: 20015 | B16: 英勇祝福 | C16: 2 | D16: 2 | E16: 1 | F16: 2 | G16: 4 | H16: 2 | I16: 0 | J16: 无目标 | K16: 5 | L16: 6 | M16: 3 | N16: 1 | O16: 1 | P16: 本回合，所有我方单位攻击力临时提升{0}，回合结束恢复 | Q16: 固定值，目的是配合单位数量流派，如果有多次使用，可以叠加 | V16: 0 | AB16: 打出该法术后的生效时间内，所有新打出的单位球在body处生成一个📦Effect_AttackUp特效播放1次，并跟随该单位球进行移动 （通用特效：当前攻击力大于原始攻击力的单位，body处始终循环播放📦Effect_AttackUp_Loop特效，并跟随单位球移动，直到不满足条件或死亡） | AC16: 英勇祝福之类的 | AE16: Times | AF16: 1 | AG16: ContinueAddBuffToSelf | AJ16: 0
A17: 20016 | B17: 引力炸弹 | C17: 2 | D17: 2 | E17: 1 | F17: 4 | G17: 4 | H17: 4 | I17: 0 | J17: 无目标 | K17: 5 | L17: 6.4 | M17: 3 | P17: 以我方英雄位置为中心，产生一个引力 | Q17: 隐藏参数力大小{0} | V17: 3,4 | AB17: 法术发动时，在对应英雄球body位置生成一个📦Effect_Magic16_Flash播放1次，引力效果在特效播放后0.2s发动，该特效不跟随球移动 | AC17: 引力 | AE17: Times | AF17: 1 | AG17: AddGravitationToHero | AJ17: 0 | AK17: 1
A18: 20017 | B18: 精准爆破 | C18: 2 | D18: 2 | E18: 1 | F18: 3 | G18: 4 | H18: 2 | I18: 3 | J18: 随机位置 （敌方单位几何圆心重心） | K18: 6 | L18: 5 | M18: 1 | P18: 指定战场位置，生成{1}个爆炸桶，爆炸伤害为{2} | Q18: 指定位置有单位和场景物件时尝试推开单位，或推开自身，该推开做成通用功能。交互物{0} | V18: 4,5 | W18: 41 | X18: 61 | Z18: 10001 | AB18: （通用特效：召唤单位和生成物，在要召唤单位的位置播放📦Effect_Summon） （通用爆炸桶特效：爆炸桶触发效果或摧毁时，在爆炸桶位置生成并播放一个📦DamageDebrisParticle； 爆炸桶触发爆炸效果时，在爆炸桶位置播放1个📦Effect_BlastBarrel_Bomb，该特效跟随范围数值缩放） | AC18: 84 | AE18: Times | AF18: 1 | AG18: AddInteractiveObjectAppointPosition | AJ18: 0 | AK18: 1
A19: 20018 | B19: 引导 | C19: 2 | D19: 2 | E19: 1 | F19: 4 | G19: 3 | H19: 2 | I19: 0 | J19: 高价值敌方单位 | K19: 3 | L19: 7 | M19: 3 | N19: 1 | O19: 1 | P19: 碰到首个单位时，我方英雄向其位移 | Q19: 隐藏参数力大小{0}，回合结束标记消失 | V19: 3 | AB19: 发射飞行道具📦Effect_Magic18_Fly,触碰到首个可触发的单位时消失，在碰撞到的单位Body位置生成一个标记特效📦Effect_Magic18_Mark循环播放，跟随移动，回合结束消失 | AC19: 108 | AE19: Times | AF19: 1 | AG19: HeroMove2Collider | AJ19: 1 | AK19: 1
A20: 20019 | B20: 变大！ | C20: 2 | D20: 2 | E20: 1 | F20: 2 | G20: 2 | H20: 1 | I20: 3 | J20: 高价值敌方单位 | K20: 3 | L20: 2 | M20: 1 | N20: 1 | O20: 1 | P20: 使碰撞的首个单位变大{0}% | Q20: 隐藏参数质量增大{1}%，可加法叠加，敌我方都可，英雄注意大蛇，直接变宽，未来可以隐藏设定统一的变大变小的极限值 | V20: 3,4,5 | AB20: 发射飞行道具📦Effect_Magic19_Fly,触碰到首个可触发的单位时消失，在碰撞到的单位Body位置生成一个特效📦Effect_Magic19播放1次后消失，不跟随移动 飞行道具触碰到首个可触发单位的同时，该单位球0.3s内ease out插值缩放至效果大小 | AC20: 98 | AE20: Times | AF20: 1 | AG20: CollisionChangeVolume | AJ20: 1 | AK20: 1
A21: 20020 | B21: 缩小！ | C21: 2 | D21: 2 | E21: 1 | F21: 2 | G21: 2 | H21: 1 | I21: 3 | J21: 高价值我方单位 | K21: 3 | L21: 2 | M21: 1 | N21: 1 | O21: 1 | P21: 使碰撞的首个单位变小{0}% | Q21: 隐藏参数质量减小{1}%，其他同上 | V21: 0 | AB21: 发射飞行道具📦Effect_Magic20_Fly,触碰到首个可触发的单位时消失，在碰撞到的单位Body位置生成一个特效📦Effect_Magic19播放1次后消失，不跟随移动 飞行道具触碰到首个可触发单位的同时，该单位球0.3s内ease out插值缩放至效果大小 | AC21: 98 | AE21: Times | AF21: 1 | AG21: CollisionChangeVolume | AJ21: 1 | AK21: 1
A22: 20021 | B22: 精准引导 | C22: 2 | D22: 2 | E22: 1 | F22: 4 | G22: 4 | H22: 4 | I22: 3 | J22: 高价值敌方单位 | K22: 6 | L22: 7 | M22: 3 | P22: 指定战场任意位置，我方英雄向该位置位移 | Q22: 隐藏参数位移力度{0}，不能移动的英雄不生效 | V22: 3 | W22: 41 | AB22: 发动法术后，在指定的战场位置生成一个📦Effect_Magic21_Mark，英雄在延迟0.4s后向目标方向位移，该标记存在3s后消失 | AC22: 109 | AE22: Times | AF22: 1 | AG22: HeroMove2AppointPosition | AJ22: 0 | AK22: 1
A23: 20022 | B23: 蓄力 | C23: 2 | D23: 2 | E23: 1 | F23: 2 | G23: 1 | H23: 2 | I23: 3 | J23: 无目标 | K23: 5 | L23: 2 | M23: 1 | N23: 1 | O23: 1 | P23: 下一张打出的卡牌，发射速度增加{0}% | V23: 0 | AB23: 下一张打出若是单位牌，单位移动时会在Body位置附带📦Effect_Magic22_Trail特效跟随单位球移动，生成特效时，将单位球的当前帧图像应用至🌍Effect_Magic22_Trail材质球的MainTex 该特效在此单位球首次停止移动后消失 下一张打出的若是法术牌，则暂时只应用速度增加效果，不附带额外特效 | AC23: 117 | AE23: Times | AF23: 1 | AG23: SkillCardAddShootCardSpeed | AJ23: 0
A24: 20023 | B24: 弹簧安装 | C24: 2 | D24: 2 | E24: 1 | F24: 2 | G24: 2 | H24: 3 | I24: 3 | J24: 随机空地 （敌方或场上单位几何圆心重心） | K24: 6 | L24: 2 | M24: 1 | P24: 指定战场位置，生成一个弹簧，被单位碰撞到时施加弹力 | Q24: 同上推开规则。场景要素默认都是敌我方都有效，增加推力参数{1}，覆盖交互物的设置.交互物{0}.碰撞{2}次后消失 | V24: 4,5 | W24: 41 | Z24: 10002 | AB24: （通用特效：召唤单位和生成物，在要召唤单位的位置播放📦Effect_Summon） （通用弹簧特效：弹簧摧毁时，在弹簧位置生成并播放一个📦DamageDebrisParticle） | AE24: Times | AF24: 1 | AG24: InstallSpring | AJ24: 0 | AK24: 1
A25: 20024 | B25: 裂地斩 | C25: 2 | D25: 2 | E25: 1 | F25: 2 | G25: 4 | H25: 4 | I25: 0 | J25: 高价值敌方单位 （所有单位几何重心或圆心） | K25: 7 | L25: 2 | M25: 3 | P25: 场景穿透，路径上产生一条裂缝，受到{1}点伤害后消失 | Q25: 单位碰到裂缝反弹跟墙一样特性，投射物可以穿过，裂缝可以叠着，可以跨回合存在，发射时注意底边裂缝处理，产生裂缝时挤开单位，增加产生裂缝时向两边的力。隐藏参数力大小{0} | V25: 5 | W25: 8 | AB25: 发动法术后，从发射点位置生成并播放📦Effect_Magic24_Wall，生成时的旋转角度与操作发射角度相同，同时生成碰撞体，回合结束时特效和碰撞体消失 | AC25: 97 | AE25: Times | AF25: 1 | AG25: AddInteractiveObject | AJ25: 0 | AK25: 1
A26: 20025 | B26: 修建工事 | C26: 2 | D26: 2 | E26: 1 | F26: 2 | G26: 3 | H26: 3 | I26: 1 | J26: 无目标 | K26: 5 | L26: 2 | M26: 3 | P26: 在战场中间产生一堵由障碍物组成的墙，墙体血量为{1} | Q26: 尝试用障碍物场景物件横向排列而成，排不下则停下，例如大蛇存在时战场变小，相应墙也会缩短。交互物ID{0} | V26: 5 | Z26: 10005 | AB26: 从战场（0,0）位置开始向两侧以0.05s每个的速度生成障碍物，直至无法生成为止 （通用特效：召唤单位和生成物，在要召唤单位的位置播放📦Effect_Summon） （通用障碍物特效：障碍物摧毁时，在障碍物位置生成并播放一个📦DamageDebrisParticle） | AE26: Times | AF26: 1 | AG26: AddInteractiveObjectToSpecialPosition | AJ26: 0 | AK26: 1
A27: 20026 | B27: 风暴针刺 | C27: 2 | D27: 2 | E27: 1 | F27: 4 | G27: 4 | H27: 3 | I27: 0 | J27: 高价值敌方单位 | K27: 7 | L27: 8.5 | M27: 3 | P27: 根据本回合已打出的牌数，发射数根能量针，每个造成{0}点伤害 | Q27: 投射物首次碰到敌方单位或墙就会消失，隐藏参数宽度{1}，宽度决定投射物随机生成的左右范围 | V27: 2 | W27: 8 | AB27: 发动法术后，从随机出来的发射点位置生成并播放📦Effect_Magic26_Shoot，生成时的旋转角度与操作发射角度相同，发射间隔为0.35s/个；每次发射的特效播放0.15s后，，若对路径上的首个单位造成了伤害，则在受到伤害的单位Body处播放1个📦Effect_Magic26_Hit | AC27: 62 | AE27: Times | AF27: 1 | AG27: MultiRaycastCauseDamage | AJ27: 0 | AK27: 1
A28: 20027 | B28: 嗜血杀戮 | C28: 2 | D28: 2 | E28: 1 | F28: 2 | G28: 5 | H28: 3 | I28: 0 | J28: 无目标 | K28: 5 | L28: 2 | M28: 3 | N28: 1 | O28: 1 | P28: 保留，本回合接下来的时间，我方英雄每杀死一个单位，攻击力永久增加{0} | V28: 3,4,5 | W28: 36 | AB28: 发动法术后，在获得效果的对应英雄球处生成并播放1次📦Effect_Magic27 每次触发提升攻击力效果时，在自身球body处生成一个📦Effect_AttackUp特效播放1次，并跟随该单位球进行移动 （通用特效：当前攻击力大于原始攻击力的单位，body处始终循环播放📦Effect_AttackUp_Loop特效，并跟随单位球移动，直到不满足条件或死亡） | AC28: 53 76 | AE28: Times | AF28: 1 | AG28: HeroKillEnemyAddAttack | AJ28: 0 | AK28: 1
A29: 20028 | B29: 冰冻炸弹 | C29: 2 | D29: 2 | E29: 1 | F29: 3 | G29: 3 | H29: 3 | I29: 0 | J29: 高价值敌方单位 （所有单位周围伤害价值中取最高） | K29: 4 | L29: 5 | M29: 3 | N29: 1 | O29: 1 | P29: 碰到首个敌方时，对范围内的敌方单位造成{0}点伤害并冻结 | Q29: 隐藏参数范围大小{1}，对场景也生效，包括水地面，会变成冰地面。 | V29: 0 | W29: 44 | AB29: 发动法术后，从发射点生成飞行道具📦Effect_Magic28_Fly，按照操作发射方向飞出，触发效果后消失，触发效果时，在触发位置生成并播放1次📦Effect_Magic28_Boom，该特效跟随范围数值缩放 | AC29: 68 109 | AE29: Times | AF29: 1 | AG29: CollisionCauseRangeDamageAndAddBuffOnce | AJ29: 1 | AK29: 1
A30: 20029 | B30: 人工降雨 | C30: 2 | D30: 2 | E30: 1 | F30: 2 | G30: 2 | H30: 3 | I30: 3 | J30: 无目标 | K30: 5 | L30: 2 | M30: 1 | N30: 1 | O30: 1 | P30: 召唤雨天天气，回合结束消散 | Q30: 熄灭（去掉点燃buff）场上所有单位尝试挂上潮湿buff，隐藏参数天气类型{0}，这个技能本回合结束就消失，若是有多个天气时，后出者覆盖前出者 | R30: 召唤雨天天气，生成{0}个水面，{1}回合后消失 | S30: 熄灭（去掉点燃buff）场上所有单位尝试挂上潮湿buff，隐藏参数天气类型{2}，若是有多个天气时，后出者覆盖前出者 | T30: 召唤雨天天气，生成{0}个水面，{1}回合后消失 | U30: 熄灭（去掉点燃buff）场上所有单位尝试挂上潮湿buff，隐藏参数天气类型{2}，若是有多个天气时，后出者覆盖前出者 | V30: 0 | W30: 54 | AB30: 发动法术后，在战场（0,0）位置生成一个特效📦Effect_Weather_Rain，回合结束时消失 | AC30: 113rain | AE30: Times | AF30: 1 | AG30: SummonWeather | AJ30: 0 | AK30: 1
A31: 20030 | B31: 雷枪 | C31: 2 | D31: 1 | E31: 1 | F31: 3 | G31: 3 | H31: 2 | I31: 0 | J31: 高价值敌方单位 | K31: 6 | L31: 5 | M31: 3 | P31: 指定位置，召唤一道雷电，对最近的敌方单位造成一次{0}点电击伤害 | Q31: 隐藏效果，打出时若是雨天，则将天气转化成雷雨天 | V31: 0 | W31: 41 | X31: 47 | AB31: 对选定位置最近的敌方单位Body处生成一道雷击特效📦Effect_Magic30_Hit播放特效后0.1s再触发实际的法术效果（伤害和电击） | AC31: 转换为雷雨天气时，销毁原本的雨天特效，在战场（0,0）位置生成一个特效📦Effect_Weather_Thunderstorm 雷雨天气的攻击特效使用雷击特效📦Effect_Magic30_Hit播放特效后0.1s再触发实际的法术效果（伤害和电击） 液体地面液体地面感电特效为：在触发感电效果的所有液体地面地块中心点播放一个📦Effect_Electrocution1 | AE31: Times | AF31: 1 | AG31: SummonThunder | AJ31: 0 | AK31: 1
A32: 20031 | B32: 滋水 | C32: 2 | D32: 2 | E32: 1 | F32: 3 | G32: 3 | H32: 1 | I32: 0 | J32: 高价值敌方单位 | K32: 7 | L32: 5 | M32: 3 | N32: 1 | O32: 1 | P32: 对触碰的首个敌方单位造成{0}点伤害，并赋予潮湿状态 | Q32: 凑数技能，水瓶娘滋水，对碰到的我方也会赋予潮湿 | R32: 场景穿透，对触碰的所有敌方单位造成{0}点伤害，并赋予潮湿状态 | S32: 隐藏参数宽度{1}，递进第二级滋水。隐藏效果，对碰到的我方赋予潮湿 | T32: 场景穿透，发射水柱击退路径上的所有敌方单位，造成{0}点伤害，并赋予潮湿状态 | U32: 隐藏参数宽度{1}，隐藏参数击退力度{2}，留下水地面，第三级递进滋水。隐藏效果，对碰到的我方赋予潮湿和一样的推力 | V32: 0 | W32: 8 | X32: 45 | AB32: 发动法术后，从发射点生成飞行道具📦Effect_Magic31_Fly，按照操作发射方向飞出，触发效果后消失，触发效果时，在被击中的单位球Body处生成并播放1次📦Effect_Water_Hit，该特效跟随单位球移动 | AC32: 80 | AE32: Times | AF32: 1 | AG32: SceneThroughCauseDamageAndAddBuffOnce | AH32: SceneThroughCauseDamageAndAddBuff | AI32: SceneThroughCauseDamageAddForceAndAddBuff | AJ32: 0
A33: 20034 | B33: 补水计划 | C33: 2 | D33: 2 | E33: 1 | F33: 3 | G33: 6 | H33: 4 | I33: 3 | J33: 无目标 | K33: 5 | L33: 5 | M33: 1 | P33: 保留，打出时每有一个敌方单位，手牌中生成一张临时的纯净水-浅浅 | Q33: 隐藏参数生成卡ID{0} | V33: 1，2 | W33: 36 | X33: 3 | AB33: 发动法术后，从每个敌方单位Body位置生成一个📦Effect_Magic34_Fly，0.5s内ease in out插值飞至对应方手牌区域中心位置，到达终点后消失 | AC33: 80 | AE33: Times | AF33: 1 | AG33: AddHandCard | AJ33: 0 | AK33: 1
A34: 20035 | B34: 冰霜新星 | C34: 2 | D34: 2 | E34: 1 | F34: 2 | G34: 5 | H34: 4 | I34: 3 | J34: 无目标 | K34: 5 | L34: 5 | M34: 1 | P34: 冻结场上的所有单位 | Q34: 同样冻结所有液体地面和可冻结场景物件 | W34: 44 | AB34: 发动法术后，在战场(0,0)丶位置生成一个📦Effect_Magic35特效播放1次，播放特效后0.45s再触发实际的法术效果（冰冻这些） | AC34: 112 | AE34: Times | AF34: 1 | AG34: AddBuffToAllEntity | AJ34: 0 | AK34: 1
A35: 20036 | B35: 巨雷枪 | C35: 2 | D35: 2 | E35: 1 | F35: 4 | G35: 4 | H35: 4 | I35: 0 | J35: 覆盖更多敌方单位 （最多击杀） | K35: 7 | L35: 5 | M35: 3 | P35: 场景穿透，对敌方单位造成{0}点电击伤害，每穿过一个敌方，生成一张临时的雷枪 | Q35: 蔓延的电击伤害击杀也算，隐藏效果，打出时若是雨天，则将天气转化成雷雨天，隐藏参数生成卡ID{1}，隐藏参数宽度{2}，增加对经过的场景物件的伤害 | V35: 2 | W35: 8 | X35: 47 | Y35: 3 | AB35: 发动法术后，从发射点位置生成并播放1次📦Effect_Magic36_Shoot，生成时的旋转角度与操作发射角度相同，特效播放0.15s后，在受到此技能伤害判定的所有单位球处播放1次📦Effect_Magic36_Hit，此特效不跟随单位球移动，同时造成伤害 | AC35: 转换为雷雨天气时，销毁原本的雨天特效，在战场（0,0）位置生成一个特效📦Effect_Weather_Thunderstorm 雷雨天气的攻击特效使用雷击特效📦Effect_Magic30_Hit播放特效后0.1s再触发实际的法术效果（伤害和电击） 液体地面液体地面感电特效为：在触发感电效果的所有液体地面地块中心点播放一个📦Effect_Electrocution1 | AE35: Times | AF35: 1 | AG35: SceneThroughCauseElectricshock | AJ35: 0 | AK35: 1
A36: 20037 | B36: 投石支援 | C36: 2 | D36: 2 | E36: 1 | F36: 3 | G36: 4 | H36: 4 | I36: 0 | J36: 覆盖更多敌方单位 （圆形范围敌方最多） | K36: 6 | L36: 5 | M36: 3 | P36: 指定战场任意位置，对范围内的敌方单位造成{0}点伤害并眩晕{1}层 | Q36: 隐藏参数范围{2}，敌我双方都生效,眩晕ID{3} | R36: 指定战场任意位置，掉落石头对较大范围内的敌方单位造成{0}点伤害并眩晕{1}层 | S36: 隐藏参数范围{2}，敌我双方都生效，眩晕ID{3} | T36: 指定战场任意位置，掉落石头对大范围内的敌方单位造成{0}点伤害并眩晕{1}层 | U36: 隐藏参数范围{2}，敌我双方都生效，眩晕ID{3} | V36: 0 | W36: 41 | X36: 52 | AB36: 发动法术后，在指定的位置播放📦Effect_Magic37_Hit特效1次，特效播放0.2s后触发范围伤害及眩晕效果，该特效跟随范围配置进行缩放 | AC36: 60 | AE36: Times | AF36: 1 | AG36: CauseDamageAndAddBuffAtAppointPosition | AJ36: 0 | AK36: 1
A37: 20038 | B37: 飞砖 | C37: 2 | D37: 2 | E37: 1 | F37: 3 | G37: 2 | H37: 2 | I37: 0 | J37: 高价值敌方单位 | K37: 3 | L37: 5 | M37: 3 | P37: 碰到首个敌方单位时，对其造成{0}点伤害并眩晕{1}层 | Q37: 眩晕技能ID{2} | V37: 0 | W37: 52 | AB37: 发动法术后，从发射点生成飞行道具📦Effect_Magic38_Fly，按照操作发射方向飞出，触发效果后消失，触发效果时，在触发位置生成并播放1次📦Effect_Magic38_Hit | AC37: 68zhuan | AE37: Times | AF37: 1 | AG37: CollisionCauseDamageAndAddBuffOnce | AJ37: 1 | AK37: 1
A38: 20039 | B38: 战术核武 | C38: 2 | D38: 2 | E38: 1 | F38: 4 | G38: 4 | H38: 4 | I38: 1 | J38: 无目标 | K38: 5 | L38: 5 | M38: 3 | P38: 保留，对所有单位和场景物件造成{0}点伤害并点燃 | Q38: 敌我双方都受伤，位置为战场中心，并且有力向周围，隐藏参数推动力{1} | V38: 4,5 | W38: 36 | X38: 43 | AB38: 发动法术后，在战场(0,0)丶位置生成一个📦Effect_Magic39_Boom特效播放1次，播放特效后0.3s再触发实际的法术效果（伤害和推力） | AC38: 82 | AE38: Times | AF38: 1 | AG38: CauseDamageAndAddBuffToAllEntity | AJ38: 0 | AK38: 1
A39: 20040 | B39: 混乱补给 | C39: 2 | D39: 2 | E39: 1 | F39: 2 | G39: 2 | H39: 2 | I39: 3 | J39: 无目标 | K39: 5 | L39: 5 | M39: 1 | N39: 1 | O39: 1 | P39: 在随机空地召唤{0}个礼物盒，被碰撞若干次后打开，打开的玩家获得随机奖励 | Q39: 局外货币，全体回血，全体加攻等等都可，预期三回合打开 | V39: 0 | Z39: 10004 | AB39: （通用特效：召唤单位和生成物，在要召唤单位的位置播放📦Effect_Summon） （通用礼物盒特效：礼物盒摧毁时，在礼物盒位置生成并播放一个📦DamageDebrisParticle） 礼物盒被摧毁时，根据随机效果在礼物盒位置生成对应动画 全体加攻时：所有被加攻的单位播放通用加攻效果 全体回复时：所有被回复的单位播放通用恢复效果 | AE39: Times | AF39: 1 | AG39: ChaosSupply | AJ39: 0 | AK39: 1
A40: 20041 | B40: 冰冻陷阱 | C40: 2 | D40: 2 | E40: 1 | F40: 2 | G40: 2 | H40: 3 | I40: 0 | J40: 无目标 | K40: 5 | L40: 3 | M40: 3 | P40: 在随机空地召唤{0}个陷阱，将敌方单位推入时造成{1}伤害，眩晕{2}层并冻结，陷阱触发后消失 | Q40: 回合结束不消失，直到一方推入另一方。我的回合，敌方会触发陷阱，反过来敌方回合就是我方触发陷阱。非主动回合一方会触发陷阱 | V40: 0 | Z40: 10003 | AB40: （通用特效：召唤单位和生成物，在要召唤单位的位置播放📦Effect_Summon） （通用陷阱特效：礼物盒摧毁时，在礼物盒位置生成并播放一个📦DamageDebrisParticle 陷阱触发伤害效果时，陷阱播放触发动画，同时在受到陷阱伤害的单位球处生成并播放1次📦Effect_Trap_Hit特效，该特效跟随单位球移动） | AC40: 108 | AE40: Times | AF40: 1 | AG40: AddInteractiveObjectAtRandomPosition | AJ40: 0 | AK40: 1
...

Sheet 组件分表
A1: 组件卡的组ID | B1: 对应组件卡ID | C1: 组件名 | D1: 卡牌类型 | E1: 组件类型 | F1: 价格 | G1: 初始星级 | H1: 最大星级 | I1: 获取方式类型 | J1: 废弃 | K1: 不放入商店 | L1: 组件主动效果，被破坏后失效 | M1: 效果备注 | N1: 2星效果 | O1: 3星效果 | P1: 4星效果 | Q1: 5星效果 | R1: 特性列表（特性ID） | T1: KeyID | U1: 引用交互物列表（交互物ID） | V1: 技能表现 | W1: 失效类型 | X1: 失效参数 | Y1: 射击操作类型 | Z1: 是否需要物理模拟 | AA1: 职业 | AB1: 瞄准线类型 | AC1: 牌序标签类型
A2: 4001 | B2: {=_xlfn.XLOOKUP(A2,组件ID生成表!B:B,组件ID生成表!C:C,"没配置")} -> 40011 | C2: 初始炮 | D2: 5 | E2: 2 | F2: 5 | G2: 1 | H2: 1 | I2: 3 | L2: 打出时，回合开始时：开炮，伤害为{0} | M2: 用作默认 | R2: ArkPartNormalGun | S2: {0:炮弹ID，1:偏移角度} | T2: 36
A3: 4002 | B3: {=_xlfn.XLOOKUP(A3,组件ID生成表!B:B,组件ID生成表!C:C,"没配置")} -> 40021 | C3: 过渡炮 | D3: 5 | E3: 2 | F3: 5 | G3: 1 | H3: 1 | I3: 3 | L3: 打出时，回合开始时：开炮，伤害为{0}，被替换时获得{2}金币 | M3: 替换的意思是再买一门炮时的替换，破坏不算 | N3: 伤害+ | R3: ArkPartTransitionGun | S3: {0:炮弹ID，1:偏移角度，2:金币数} | T3: 36
A4: 4003 | B4: {=_xlfn.XLOOKUP(A4,组件ID生成表!B:B,组件ID生成表!C:C,"没配置")} -> 40032 | C4: 英雄炮 | D4: 5 | E4: 2 | F4: 6 | G4: 2 | H4: 2 | I4: 3 | L4: 打出时，回合开始时：向敌方英雄开炮，伤害为{0} | M4: 无英雄时向前开炮 | O4: 伤害+ | P4: 伤害+ | R4: ArkPartHeroGun | S4: {0:炮弹ID} | T4: 36
A5: 4004 | B5: {=_xlfn.XLOOKUP(A5,组件ID生成表!B:B,组件ID生成表!C:C,"没配置")} -> 40043 | C5: 精英炮 | D5: 5 | E5: 2 | F5: 9 | G5: 3 | H5: 3 | I5: 3 | L5: 打出时，回合开始时：向敌方攻击最高单位开炮，伤害为{0} | O5: 伤害+ | P5: 伤害+ | R5: ArkPartCreatureGun | S5: {0:炮弹ID} | T5: 36
A6: 4005 | B6: {=_xlfn.XLOOKUP(A6,组件ID生成表!B:B,组件ID生成表!C:C,"没配置")} -> 40054 | C6: 方舟炮 | D6: 5 | E6: 2 | F6: 12 | G6: 4 | H6: 4 | I6: 3 | L6: 打出时，回合开始时：开炮，伤害为{0}，对方舟伤害增加{2}% | O6: 伤害+ | P6: 对方舟伤害++ | Q6: 伤害+，对方舟伤害+ | R6: ArkPartArkGun | S6: {0:炮弹ID，1:偏移角度，2:伤害增加百分比} | T6: 36
A7: 4006 | B7: {=_xlfn.XLOOKUP(A7,组件ID生成表!B:B,组件ID生成表!C:C,"没配置")} -> 40062 | C7: 打牌炮 | D7: 5 | E7: 2 | F7: 6 | G7: 2 | H7: 2 | I7: 3 | L7: 每打{1}张牌，向打牌方向开炮，伤害为{0} | P7: 门槛2 | Q7: 门槛1 | R7: ArkPartShootCardGun | S7: {0:炮弹ID，1:出牌数量} | T7: 36
A8: 4007 | B8: {=_xlfn.XLOOKUP(A8,组件ID生成表!B:B,组件ID生成表!C:C,"没配置")} -> 40074 | C8: 冰冻炮 | D8: 5 | E8: 2 | F8: 12 | G8: 4 | H8: 4 | I8: 3 | L8: 打出时，回合开始时：向{1}个敌方单位开炮，伤害为{0}，对击中的敌方赋予冰冻 | P8: 冰冻数量+1 | R8: ArkPartFreezeGun | S8: {0:炮弹ID，1:目标数量} | T8: 36
A9: 4008 | B9: {=_xlfn.XLOOKUP(A9,组件ID生成表!B:B,组件ID生成表!C:C,"没配置")} -> 40085 | C9: 一次性卡炮 | D9: 5 | E9: 2 | F9: 12 | G9: 5 | H9: 5 | I9: 3 | L9: 打出时，回合开始时：开炮，伤害为{0}，本局战斗，每获得过{2}张商店一次性卡，伤害增加{3} | M9: 前端可以显示一下当前总伤害累计多少 | P9: 伤害增量+ | Q9: 门槛2 | R9: ArkPartTempCardGun | S9: {0:炮弹ID，1:偏移角度，2：获得卡片数量，3：增加伤害} | T9: 36
A10: 4009 | B10: {=_xlfn.XLOOKUP(A10,组件ID生成表!B:B,组件ID生成表!C:C,"没配置")} -> 40093 | C10: 亡语商店炮 | D10: 5 | E10: 2 | F10: 9 | G10: 3 | H10: 3 | I10: 3 | L10: 打出时，回合开始时：开炮，伤害为{0}，被替换时，获得一张比本组件星级高{2}级的一次性卡 | M10: 最大不超过5星 | O10: 售价++，拿5星卡 | R10: ArkPartReplaceGun | S10: {0:炮弹ID，1:偏移角度，2：高多少级} | T10: 36
A11: 4010 | B11: {=_xlfn.XLOOKUP(A11,组件ID生成表!B:B,组件ID生成表!C:C,"没配置")} -> 40105 | C11: 冲刺引擎 | D11: 5 | E11: 5 | F11: 12 | G11: 5 | H11: 5 | I11: 3 | L11: 我方方舟回合开始多冲撞{0}次，伤害增加{1}% | Q11: 次数+ | R11: ArkPartClashEngine | S11: {0:冲撞次数，1：伤害百分比} | T11: 36
A12: 4011 | B12: {=_xlfn.XLOOKUP(A12,组件ID生成表!B:B,组件ID生成表!C:C,"没配置")} -> 40114 | C12: 单位装填炮 | D12: 5 | E12: 2 | F12: 12 | G12: 4 | H12: 4 | I12: 3 | L12: 我方回合结束时：将{0}个随机友方单位装填进炮，我方开始时发射出去 | M12: 暂时移出战场，敌方打破这个炮，单位就掉出来，隐藏参数发射速度大小{1}，英雄跳过大蛇和花 | O12: 治疗被装填单位 | P12: 打出力道++（初始打出力道较弱） | R12: ArkPartEquipUnitGun | S12: {0:随从个数，1:力大小} | T12: 36
A13: 4012 | B13: {=_xlfn.XLOOKUP(A13,组件ID生成表!B:B,组件ID生成表!C:C,"没配置")} -> 40123 | C13: 自动打牌炮 | D13: 5 | E13: 2 | F13: 9 | G13: 3 | H13: 3 | I13: 3 | L13: 我方回合结束时：将未打且非保留的单位牌发射出去，其攻击增加{1} | M13: 和上一个实现类似，只有英雄卡，单位卡和雇佣兵卡增加属性 | O13: 增加等量生命上限 | P13: 增加更多生命 | R13: ArkPartAutoShootCardGun | S13: {0:偏移角度，1：加成百分比} | T13: 36
A14: 4013 | B14: {=_xlfn.XLOOKUP(A14,组件ID生成表!B:B,组件ID生成表!C:C,"没配置")} -> 40134 | C14: 烟雾导弹 | D14: 5 | E14: 3 | F14: 12 | G14: 4 | H14: 4 | I14: 3 | L14: 回合结束时：在随机位置产生一片烟雾，烟雾中看不到单位并且瞄准线失效 | M14: 导弹，我方回合开始时消散，隐藏参数范围{0} | P14: 范围+ | R14: ArkPartOverloadGun | S14: {0:范围大小} | T14: 36
A15: 4014 | B15: {=_xlfn.XLOOKUP(A15,组件ID生成表!B:B,组件ID生成表!C:C,"没配置")} -> 40141 | C15: 初始导弹 | D15: 5 | E15: 3 | F15: 5 | G15: 1 | H15: 1 | I15: 3 | L15: 打出时，回合开始时：对随机范围区域造成{0}伤害 | M15: 用作默认，隐藏参数范围大小{1} | R15: ArkPartNormalMissile | S15: {0:伤害，1:范围} | T15: 36
A16: 4015 | B16: {=_xlfn.XLOOKUP(A16,组件ID生成表!B:B,组件ID生成表!C:C,"没配置")} -> 40151 | C16: 过渡导弹 | D16: 5 | E16: 3 | F16: 5 | G16: 1 | H16: 1 | I16: 3 | L16: 打出时，回合开始时：对随机范围区域造成{0}伤害，被替换时获得{2}金币 | M16: 隐藏参数范围大小{1} | N16: 伤害+ | R16: ArkPartPassMissile | S16: {0:伤害，1:范围，2：获得金币数} | T16: 36
A17: 4016 | B17: {=_xlfn.XLOOKUP(A17,组件ID生成表!B:B,组件ID生成表!C:C,"没配置")} -> 40163 | C17: 蓄力核武 | D17: 5 | E17: 3 | F17: 9 | G17: 3 | H17: 3 | I17: 3 | L17: 蓄力{0}回合，回合开始时：发射一颗毁天灭地的核弹，核弹伤害为{1} | M17: 复用战术核武，伤害不同，组件被破坏则蓄力清零 | P17: 蓄力- | R17: ArkPartAccumulatePowerMissile | S17: {0:回合间隔，1:伤害} | T17: 36
A18: 4017 | B18: {=_xlfn.XLOOKUP(A18,组件ID生成表!B:B,组件ID生成表!C:C,"没配置")} -> 40173 | C18: 智能导弹 | D18: 5 | E18: 3 | F18: 9 | G18: 3 | H18: 3 | I18: 3 | L18: 打出时，回合开始时：向单位最多的位置发射炮弹，对其中的敌方造成{0}伤害，我方治疗{1}生命 | M18: 隐藏参数范围大小{2} | O18: 伤害+ | P18: 范围+ | Q18: 伤害+，范围+ | R18: ArkPartAutoMissile | S18: {0:伤害，1:恢复血量，2：范围} | T18: 36
A19: 4018 | B19: {=_xlfn.XLOOKUP(A19,组件ID生成表!B:B,组件ID生成表!C:C,"没配置")} -> 40185 | C19: 英雄导弹 | D19: 5 | E19: 3 | F19: 12 | G19: 5 | H19: 5 | I19: 3 | L19: 打出时，回合开始时：以我方英雄为中心，对范围内敌方和英雄自身造成{0}伤害 | M19: 隐藏参数范围大小{1} | P19: 范围+ | Q19: 伤害+，范围+ | R19: ArkPartHeroMissile | S19: {0:伤害，1:范围} | T19: 36
A20: 4019 | B20: {=_xlfn.XLOOKUP(A20,组件ID生成表!B:B,组件ID生成表!C:C,"没配置")} -> 40192 | C20: 液体导弹 | D20: 5 | E20: 3 | F20: 6 | G20: 2 | H20: 2 | I20: 3 | L20: 打出时，回合开始时：对随机范围区域，造成{0}伤害，赋予潮湿，并留下水地面 | M20: 敌我都潮湿，只有敌方受伤，隐藏参数范围大小{1} | O20: 伤害+ | R20: ArkPartWaterMissile | S20: {0:伤害，1:范围} | T20: 36
A21: 4020 | B21: {=_xlfn.XLOOKUP(A21,组件ID生成表!B:B,组件ID生成表!C:C,"没配置")} -> 40204 | C21: 加速导弹 | D21: 5 | E21: 3 | F21: 12 | G21: 4 | H21: 4 | I21: 3 | L21: 打出时，回合开始时：在随机区域生成{0}个加速地面 | M21: 加速地面新场景物件，经过的单位加速并且加速地面消失 | P21: 数量+ | R21: ArkPartAccelerateMissile | S21: {0：地面数量，1:范围半径，2:力} | T21: 36
A22: 4021 | B22: {=_xlfn.XLOOKUP(A22,组件ID生成表!B:B,组件ID生成表!C:C,"没配置")} -> 40212 | C22: 掩体导弹 | D22: 5 | E22: 3 | F22: 6 | G22: 2 | H22: 2 | I22: 3 | L22: 回合结束时：围绕我方生命最低单位召唤{0}个掩体，掩体生命为{2}，我方回合开始时移除 | M22: 导弹，数量较多，高星可以比修建阵地夸张一些，影响对方碰撞来保护单位 | P22: 掩体数量+ | R22: ArkPartAddInteractiveAircraft | S22: {0：交互物数量，1:交互物ID，2:掩体血量} | T22: 36
A23: 4022 | B23: {=_xlfn.XLOOKUP(A23,组件ID生成表!B:B,组件ID生成表!C:C,"没配置")} -> 40221 | C23: 初始治疗引擎 | D23: 5 | E23: 5 | F23: 5 | G23: 1 | H23: 1 | I23: 3 | L23: 打出时，回合开始时：治疗生命比例最低的我方{0}点生命 | M23: 初始默认 | R23: ArkPartCureEngine | S23: {0：恢复血量} | T23: 36
A24: 4023 | B24: {=_xlfn.XLOOKUP(A24,组件ID生成表!B:B,组件ID生成表!C:C,"没配置")} -> 40232 | C24: 转运无人机 | D24: 5 | E24: 4 | F24: 6 | G24: 2 | H24: 2 | I24: 3 | L24: 打出时，回合开始时：从我方生命最高随从转移{0}生命上限到我方英雄身上 | O24: 转移量+ | P24: 转移量+ | R24: ArkPartTransportAircraft | S24: {0：转移血量} | T24: 36
A25: 4024 | B25: {=_xlfn.XLOOKUP(A25,组件ID生成表!B:B,组件ID生成表!C:C,"没配置")} -> 40242 | C25: 猎杀无人机 | D25: 5 | E25: 4 | F25: 6 | G25: 2 | H25: 2 | I25: 3 | L25: 我方回合：将生命最低的敌方单位变大{0}% | M25: 质量也对应变大{1}%，过程中生命最低单位变化则切换，包括击杀，敌方回合恢复 | R25: ArkPartHuntingAircraft | S25: {0：增加百分比} | T25: 36
A26: 4025 | B26: {=_xlfn.XLOOKUP(A26,组件ID生成表!B:B,组件ID生成表!C:C,"没配置")} -> 40255 | C26: 目标无人机 | D26: 5 | E26: 4 | F26: 12 | G26: 5 | H26: 5 | I26: 3 | L26: 打出时，回合开始时：随机标记{0}个敌方单位，标记单位受伤增加{1}%，最大叠加{2}层 | M26: 回合结束移除标记 | P26: 标记数量2，标记可叠加2层 | Q26: 标记数量4，标记可叠加3层 | R26: ArkPartTargetAircraft | S26: {0：标记敌方数，1:伤害增加百分比，2:最大叠加层数} | T26: 36
A27: 4026 | B27: {=_xlfn.XLOOKUP(A27,组件ID生成表!B:B,组件ID生成表!C:C,"没配置")} -> 40263 | C27: 变强无人机 | D27: 5 | E27: 4 | F27: 9 | G27: 3 | H27: 3 | I27: 3 | L27: 每当我方单位（分裂体除外）死亡或离场，他在本局对战中的攻击永久增加{0} | M27: 包括英雄 | O27: 攻击+ | P27: 攻击++ | R27: ArkPartStrongAircraft | S27: {0：攻击值} | T27: 36
A28: 4027 | B28: {=_xlfn.XLOOKUP(A28,组件ID生成表!B:B,组件ID生成表!C:C,"没配置")} -> 40274 | C28: 粘合无人机 | D28: 5 | E28: 4 | F28: 12 | G28: 4 | H28: 4 | I28: 3 | L28: 我方回合结束时，将所有我方单位粘合到英雄上，我方回合开始时弹走黏合单位 | M28: 尝试黏上英雄直到放不下，没有英雄则失效，敌方仍旧能正常碰到不同部位，只是我方会一起行动 | P28: 英雄临时变小 | Q28: 回合开始时弹走黏合单位 | R28: ArkPartMixAircraft | T28: 36
A29: 4028 | B29: {=_xlfn.XLOOKUP(A29,组件ID生成表!B:B,组件ID生成表!C:C,"没配置")} -> 40283 | C29: 汲取无人机 | D29: 5 | E29: 4 | F29: 9 | G29: 3 | H29: 3 | I29: 3 | L29: 我方回合：我方英雄碰到雇佣兵时，吸取其{0}点攻击力 | M29: 吸到0，雇佣兵攻击不足时有多少吸多少。英雄攻击为永久增加，雇佣兵攻击减少持续至离场 | N29: 售价- | R29: ArkPartDrawAircraft | S29: {0：攻击值} | T29: 36
A30: 4029 | B30: {=_xlfn.XLOOKUP(A30,组件ID生成表!B:B,组件ID生成表!C:C,"没配置")} -> 40295 | C30: 抽卡引擎 | D30: 5 | E30: 5 | F30: 12 | G30: 5 | H30: 5 | I30: 3 | L30: 每回合抽卡数量加{0} | R30: ArkPartDrawCardEngine | S30: {0：数量} | T30: 36
A31: 4030 | B31: {=_xlfn.XLOOKUP(A31,组件ID生成表!B:B,组件ID生成表!C:C,"没配置")} -> 40302 | C31: 圣盾引擎 | D31: 5 | E31: 5 | F31: 6 | G31: 2 | H31: 2 | I31: 3 | L31: 回合结束时：为随机{0}个我方添加圣盾 | M31: 最低到1 | N31: 数量+ | O31: 数量+ | R31: ArkPartRandomAddShieldEngine | S31: {0：数量} | T31: 36
A32: 4031 | B32: {=_xlfn.XLOOKUP(A32,组件ID生成表!B:B,组件ID生成表!C:C,"没配置")} -> 40313 | C32: 生命引擎 | D32: 5 | E32: 5 | F32: 9 | G32: 3 | H32: 3 | I32: 3 | L32: 回合结束时：为所有我方永久增加{0}生命 | P32: 生命成长+ | R32: ArkPartHealthEngine | S32: {0：生命值} | T32: 36
A33: 4032 | B33: {=_xlfn.XLOOKUP(A33,组件ID生成表!B:B,组件ID生成表!C:C,"没配置")} -> 40323 | C33: 过载引擎 | D33: 5 | E33: 5 | F33: 9 | G33: 3 | H33: 3 | I33: 3 | L33: 回合开始时：对我方方舟造成一定伤害，抽{0}张卡 | M33: 和过载炮一个机制，改到这边，隐藏参数对方舟伤害{1} | O33: 自残- | R33: ArkPartOverloadEngine | S33: {0：抽卡数，1：方舟伤害像素个数，2：方舟伤害} | T33: 36
A34: 4033 | B34: {=_xlfn.XLOOKUP(A34,组件ID生成表!B:B,组件ID生成表!C:C,"没配置")} -> 40331 | C34: 猎杀引擎 | D34: 5 | E34: 5 | F34: 5 | G34: 1 | H34: 1 | I34: 3 | L34: 击杀敌方时：为所有我方回复{0}生命 | N34: 治疗+ | R34: ArkPartHuntingEngine | S34: {0：回复生命值} | T34: 36
A35: 4034 | B35: {=_xlfn.XLOOKUP(A35,组件ID生成表!B:B,组件ID生成表!C:C,"没配置")} -> 40342 | C35: 组件破坏引擎 | D35: 5 | E35: 5 | F35: 6 | G35: 2 | H35: 2 | I35: 3 | L35: 每破坏一个敌方组件，抽{0}张卡 | O35: 售价- | P35: 售价--，收益+ | R35: ArkPartDestoryArkPartEngine | S35: {0：抽卡数} | T35: 36
A36: 4035 | B36: {=_xlfn.XLOOKUP(A36,组件ID生成表!B:B,组件ID生成表!C:C,"没配置")} -> 40354 | C36: 临时卡引擎 | D36: 5 | E36: 5 | F36: 12 | G36: 4 | H36: 4 | I36: 3 | L36: 每打出{0}张临时卡，抽{1}张卡 | Q36: 门槛-（标准体验） | R36: ArkPartTempCardEngine | S36: {0：打牌数，1：抽卡数} | T36: 36
A37: 4036 | B37: {=_xlfn.XLOOKUP(A37,组件ID生成表!B:B,组件ID生成表!C:C,"没配置")} -> 40362 | C37: 急救引擎 | D37: 5 | E37: 5 | F37: 6 | G37: 2 | H37: 2 | I37: 3 | L37: 每个我方回合和敌方回合：我方英雄首次血量降至一半以下，对我方方舟造成一定伤害，为英雄回复{0}生命 | M37: 隐藏参数对方舟伤害{1} | O37: 治疗+ | P37: 自残- | R37: ArkPartFrstAidEngine | S37: {0：回复生命值，1：方舟伤害像素个数，2：方舟伤害} | T37: 36
A38: 4037 | B38: {=_xlfn.XLOOKUP(A38,组件ID生成表!B:B,组件ID生成表!C:C,"没配置")} -> 40374 | C38: 商店引擎 | D38: 5 | E38: 5 | F38: 12 | G38: 4 | H38: 4 | I38: 3 | L38: 打出时，每回合开始时：给与{0}张随机同星一次性卡 | M38: 本组件几星，给的一次性卡就是几星 | O38: 星级提升 | P38: 星级提升 | R38: ArkPartShopEngine | S38: {0：数量} | T38: 36
A39: 4038 | B39: {=_xlfn.XLOOKUP(A39,组件ID生成表!B:B,组件ID生成表!C:C,"没配置")} -> 40383 | C39: 转移引擎 | D39: 5 | E39: 5 | F39: 9 | G39: 3 | H39: 3 | I39: 3 | L39: 回合结束时：对我方英雄造成{0}伤害，为所有我方随从永久+{1}生命 | M39: 临时生命换永久加成，雇佣兵离场后生效 | O39: 生命成长+ | R39: ArkPartTransferEngine | S39: {0：英雄伤害 1：随从生命} | T39: 36
A40: 4039 | B40: {=_xlfn.XLOOKUP(A40,组件ID生成表!B:B,组件ID生成表!C:C,"没配置")} -> 40394 | C40: 方舟炮弹 | D40: 3 | E40: 0 | F40: 0 | G40: =G6 -> 4 | H40: =H6 -> 4 | I40: 3 | K40: 1 | L40: 方舟炮的炮弹 | R40: GunBullet | W40: Times | X40: 1 | Y40: 1 | Z40: 0 | AA40: 3 | AB40: 2 | AC40: 5
...

Sheet 特性表检索
A1: 特性名词 | B1: 临时版icon | C1: 特性描述 | D1: 实现细节
A2: 入场 | C2: 进入战场时触发 | D2: 被召唤入场，发射入场，移出后移入等都会触发
A3: 持续 | C3: 每个我方回合触发
A4: 临时 | C4: 使用卡牌后消失，不进入弃牌堆，回合结束未使用也消失
A5: 消耗 | C5: 使用后不进入弃牌堆，进入消耗堆，不再参与接下来的抽牌 | D5: 消耗堆不展示给玩家
A6: 弹射 | C6: 默认状态，可以和任何实体碰撞
A7: 穿透 | C7: 可穿透生物单位继续前进，但会被场景物件阻挡并反弹 | D7: 穿透后面若带数字，则意思是最多穿透几次就消失
A8: 强穿透 | C8: 可穿透除战场墙壁外的任何东西
A9: 极致穿透 | C9: 可穿透任何东西，永远是一条直线 | D9: 隐藏属性，不展示给玩家
A10: 生物触发 | C10: 命中首个生物时触发效果
A11: 跟随 | C11: 打出时，目标向打出方向位移 | D11: 位移力度根据不同情况配置
A12: 停止 | C12: 首次发射停止后，产生XX效果 | D12: 最晚回合结束
A13: 圣盾 | C13: 抵挡一次伤害后消失，圣盾不可叠加 | D13: 抵挡伤害本质是将伤害变为0，仍算一次伤害，会触发伤害次数+1。本质为持续性效果，可被沉默等效果移除
A14: 吸血 | C14: 造成伤害会为自身回复等量血量
A15: 剧毒 | C15: 造成伤害时直接消灭对方生物（非英雄） | D15: 攻击圣盾时不触发
A16: 回归 | C16: 打出的回合满足特定条件，可以回到手牌 | D16: 重置为初始状态
A17: 连击 | C17: 当前回合已经打出N张牌时生效该效果 | D17: 不算本身
A18: 激励 | C18: 在场时释放英雄技能时触发该效果
A19: 过载 | C19: 下回合英雄能量获取下降N
A20: 任务/奖励 | C20: 完成任务后会获得奖励
A21: 招募 | C21: 从牌库中召唤一个特定条件的生物
A22: 复活 | C22: 首次死亡后以一点血量复活
A23: 法术触发 | C23: 打出法术牌后触发效果，每回合只能触发一次
A24: 变形 | C24: 变形为一个指定对象 | D24: 不算死亡，等于替换为另一个单位，也不触发入场效果
A25: 发现 | C25: 从三张特定类型的卡中选择一张
A26: 沉默 | C26: 移除生物牌上的效果，包括所有增益和减益效果 | D26: 不影响当前血量，相当于一个初始进入场上的不带技能的版本
A27: 控制 | C27: 获得对方生物的控制权
A28: 移回手牌 | C28: 卡牌以初始状态移回手牌
A29: 移回抽牌库 | C29: 卡牌以初始状态移回抽牌库
A30: 丢弃卡牌 | C30: 选择特定卡牌丢入弃牌库（可以是手牌或抽牌库）
A31: 磨灭卡牌 | C31: 将特定卡牌移出本场战斗
A32: 魔免 | C32: 无视法术效果
A33: 恐惧 | C33: 每回合首次开始移动时，施加一个随机方向的力（移动方向变得随机）
A34: 揭示 | C34: 随机从牌库中抽N张展示给双方，若没有其他操作，就洗回牌库 | D34: 对该牌有其他操作，则打断洗回牌库
A35: 复制 | C35: 复制的随从拥有和本体一致的基础特性和属性，复制的卡牌同理，一模一样，只是多一个复制标签，表现也稍有不同，名字也改为XX的复制 | D35: 额外的，复制有一个复制标签，用做某些逻辑判断。例如复制标签无法被复制
A36: 亡语 | C36: 死亡时触发效果 | D36: 死亡是指血量归零或被消灭，放逐变形等不算
A37: 保留 | C37: 回合结束时保留在手牌中
A38: 铁壁X | C38: 每一层铁壁可以抵消一次碰撞伤害 | D38: 非碰撞伤害无效，0攻碰撞不消除铁壁
A39: 引导 | C39: 碰到的第一个单位停下时，目标向其位移
A40: 激怒 | C40: 向最近的敌方单位移动 | D40: 没有其他前缀限定时，即时生效

Sheet 英雄卡分表
A1: 卡牌ID | B1: 卡牌名 | C1: 称号 | D1: 星级 | E1: 卡牌类型 | F1: 选项类型 | G1: 射击类型 | H1: 英雄类型 | I1: 职业 | J1: 费用 | K1: 稀有度 | L1: 获取方式类型 | M1: AI目标规划 | N1: 瞄准线类型 | O1: 牌序规划标签 | P1: 是否需要物理模拟 | Q1: 等级上限 | R1: 英雄专属卡ID | S1: 卡牌效果 | T1: 效果备注 | U1: 卡牌效果2级 | V1: 2级效果备注 | W1: 卡牌效果3级 | X1: 3级效果备注 | Y1: 流派归类（后续用作职业划分） | Z1: 特性列表（特性ID） | AC1: Demo版本 技能表现 | AD1: 美术表现 | AF1: 卡组上限 | AG1: 卡组下限 | AH1: Demo版本 包装 | AI1: 一测版本 包装 | AK1: 失效次数 | AL1: 失效参数 | AM1: 技能类型
A2: 10000 | B2: 舰长 | C2: 传奇飞行员 | D2: 1 | E2: 4 | F2: 1 | G2: 1 | H2: Normal | I2: 1 | J2: 13 | K2: 4 | L2: 6 | M2: 常规碰撞 | N2: 1 | O2: 5 | P2: 1 | Q2: 15 | R2: 20026 | S2: 每打出{0}张卡，获得一张炸蛋 | AF2: 12 | AG2: 12
A3: 10001 | B3: 梅莉（Meli） | C3: 黏黏女王 | D3: 1 | E3: 4 | F3: 1 | G3: 1 | H3: Normal | I3: 1 | J3: 23 | K3: 4 | L3: 6 | M3: 常规碰撞 | N3: 1 | O3: 5 | P3: 1 | Q3: 15 | R3: 20081 | S3: 融合碰撞到的前{0}个友方随从，获得其当前属性和技能效果 | AC3: 触发该英雄的召唤单位效果时，不使用通用召唤特效，改为使用📦Effect_Hero1_Summon | AF3: 12 | AG3: 12 | AM3: FusionPreUnits
A4: 10002 | B4: 露娜（Luna） | C4: 最强盗贼王 | D4: 1 | E4: 4 | F4: 1 | G4: 1 | H4: Normal | I4: 1 | J4: 15 | K4: 4 | L4: 6 | M4: 常规碰撞 | N4: 1 | O4: 5 | P4: 1 | Q4: 15 | R4: 20017 | S4: 回合开始时，对随机敌方发射导弹造成{0}点爆炸伤害，我方每触发一次爆炸，所有爆炸伤害永久加{1}，范围永久增加{2} | T4: 打出N张牌累计 | AC4: 触发对随机敌方造成伤害效果时，在Hero_2英雄球位置生成一个📦Effect_Hero2_Shoot特效，该特效不跟随英雄球移动，生成时计算英雄球与目标球的角度并旋转该特效的Y值，特效播放0.05s后，在目标球位置播放一个📦Effect_Hero2_Hit并造成伤害，该特效跟随目标球移动。 | AF4: 12 | AG4: 12 | AM4: Bullet
A5: 10003 | B5: 乔艾塔（Joetta） | C5: 轻灵跃影 | D5: 1 | E5: 4 | F5: 1 | G5: 1 | H5: Normal | I5: 1 | J5: 18 | K5: 4 | L5: 6 | M5: 常规碰撞 | N5: 1 | O5: 5 | P5: 1 | Q5: 15 | R5: 20021 | S5: 每个我方回合开始时，向最近的敌方单位冲刺，回合结束时，每有{1}连击，自身攻击加{2}，生命加{3} | T5: 隐藏参数位移力{0} | AC5: 这个英雄需要游戏开始后2.3s后再发动技能 | AF5: 12 | AG5: 12 | AM5: MoveToNearestEnemy
A6: 10004 | B6: 维纳斯（Venus） | C6: 致命拥抱 | D6: 1 | E6: 4 | F6: 1 | G6: 1 | H6: Chomper | I6: 1 | J6: 18 | K6: 4 | L6: 6 | M6: 常规碰撞 | N6: 1 | O6: 5 | P6: 1 | Q6: 15 | R6: 20062 | S6: 打出时化作无法移动的花朵形态，我方回合盛开，吞噬碰到的敌方单位造成英雄攻击{0}%的伤害后吐出 | T6: 隐藏参数吐出时的位移力{1}，吐出时方向随机，吞噬单位被杀死就吐出尸体。不会造成碰撞伤害，直接吞噬 | AF6: 12 | AG6: 12 | AM6: HeroDevourEnemy
A7: 10005 | B7: 娜吉尼（Nagini） | C7: 环绕之蛇 | D7: 1 | E7: 4 | F7: 1 | G7: 1 | H7: Snake | I7: 1 | J7: 15 | K7: 4 | L7: 6 | M7: 常规碰撞 | N7: 1 | O7: 5 | P7: 1 | Q7: 15 | R7: 20016 | S7: 打出时在战场底边化作大蛇形态 | T7: 敌方回合敌方撞墙，就扣我方英雄血量，我方回合敌方撞墙，就是按英雄攻击扣其血量 | AF7: 12 | AG7: 12
A8: 10006 | B8: 梅丽莎（Melissa） | C8: 群蜂之母 | D8: 1 | E8: 4 | F8: 1 | G8: 1 | H8: Normal | I8: 1 | J8: 23 | K8: 4 | L8: 6 | M8: 常规碰撞 | N8: 1 | O8: 5 | P8: 1 | Q8: 15 | R8: 20080 | S8: 每个我方回合结束，对自身造成{0}点伤害，为所有友方随从增加{1}点生命上限 | T8: 圣盾可以抵挡自身的伤害，该效果对自身血量最低伤害到1 | AF8: 12 | AG8: 12 | AM8: AddHp2AllUnit

Sheet 场景物件表及数值
A1: 场景物件ID | B1: 场景物件名字 | C1: 场景物件效果 | D1: 效果备注 | E1: 是否受碰撞伤害 | F1: 是否免疫伤害 | G1: 是否可移动 | H1: 是否可燃 | I1: 是否导电 | J1: 是否受到电击伤害 | K1: 是否可冰冻 | L1: 血量 | M1: 参数1 | N1: 参数2 | O1: 参数3 | P1: 参数4
A2: Scene_Item_1 | B2: 爆炸桶 | C2: 被破坏时爆炸，对周围的单位和场景物件造成伤害和推力 | D2: 隐藏参数爆炸力大小{0}，爆炸伤害{1}，爆炸范围{2} | E2: 1 | F2: 0 | G2: 0 | H2: 1 | I2: 0 | J2: 0 | K2: 1 | L2: 1 | M2: 6 | N2: 80 | O2: 1.5 | P2: 0
A3: Scene_Item_2 | B3: 弹簧 | C3: 单位碰撞弹簧反弹时，额外获得一个推力 | D3: 隐藏参数推力{0}，隐藏参数碰撞{1}次后破坏 | E3: 1 | F3: 0 | G3: 0 | H3: 1 | I3: 0 | J3: 0 | K3: 1 | L3: 30 | M3: 6 | N3: 3 | O3: 0 | P3: 0
A4: Scene_Item_3 | B4: 陷阱 | C4: 将敌方推入时造成{1}伤害，冻结并眩晕{2}层，陷阱触发后消失 | D4: 非主动回合的一方触发 | E4: 0 | F4: 0 | G4: 0 | H4: 1 | I4: 0 | J4: 0 | K4: 1 | L4: 5 | M4: 150 | N4: 3 | O4: 0 | P4: 0
A5: Scene_Item_4 | B5: 礼物盒 | C5: 被碰撞{0}次后打开，随机获得一种奖励 | D5: 随机获得以下三种奖励中的一种：1获得{1}局外货币，2全体友方增加{2}点攻击，3全体友方回复{3}点血量。局外货币获得量未来做一个上限限制，以免玩家刷 | E5: 1 | F5: 0 | G5: 0 | H5: 1 | I5: 0 | J5: 0 | K5: 1 | L5: 30 | M5: 10 | N5: 10 | O5: 10 | P5: 30
A6: Scene_Item_5 | B6: 障碍物 | C6: 多碰撞几次就会被破坏 | D6: 0 | E6: 1 | F6: 0 | G6: 0 | H6: 1 | I6: 0 | J6: 0 | K6: 1 | L6: 20 | M6: 0 | N6: 0 | O6: 0 | P6: 0
A7: Scene_Item_6 | B7: 裂缝 | C7: 0 | D7: 0 | E7: 1 | F7: 0 | G7: 0 | H7: 1 | I7: 0 | J7: 0 | K7: 1 | L7: 300 | M7: 0 | N7: 0 | O7: 0 | P7: 0
A8: Scene_Item_7 | B8: 尖刺墙 | C8: 碰到尖刺墙的单位受到自身最大生命{0}%的伤害 | D8: 0 | E8: 1 | F8: 0 | G8: 0 | H8: 0 | I8: 0 | J8: 0 | K8: 0 | L8: 50 | M8: 2 | N8: 0 | O8: 0 | P8: 0
A9: Scene_Item_8 | B9: 掩体 | C9: 多碰撞几次就会被破坏 | D9: 0 | E9: 1 | F9: 0 | G9: 0 | H9: 0 | I9: 0 | J9: 0 | K9: 0 | L9: 10 | M9: 0 | N9: 0 | O9: 0 | P9: 0
A10: Scene_Item_9
A11: Scene_Item_10
A12: Scene_Item_11

Sheet 机制总表（参考）
A1: 卡牌类型 | B1: 流派归类（后续用作职业划分） | C1: 设计归类 | D1: 生效类型（1弹射参与碰撞，2弹射穿透，3直接生效，4拖选目标） | E1: 卡牌效果 | F1: 衍生牌数
A2: 生物 | B2: 人海流 | C2: 生物数量 | D2: 1 | E2: 每个回合开始时，生成一个自身的复制体，血量继承 | F2: 1 | H2: 卡牌设计原则：
A3: 生物 | B3: 人海流 | C3: 生物数量 | D3: 1 | E3: 当场上我方单位大于等于5时，攻击力提升 | F3: 1 | H3: 1持续备战类，需要高能耗，且低攻击。来控制玩家整体带的数量在一个合理范围内。核心目的是保证场上需要理解学习的持续重要单位，保持在一个合理数量之内
A4: 生物 | B4: 人海流 | C4: 生物数量，位移，弹射 | D4: 1 | E4: 对碰撞到的我方单位施加一个较大的力 | F4: 1
A5: 生物 | B5: 人海流 | C5: 生物数量，燃血 | D5: 1 | E5: 我方回合碰到我方英雄时，扣除英雄一定血量，生成一个新单位 | F5: 1
A6: 法术 | B6: 人海流 | C6: 生物数量，穿透 | D6: 2 | E6: 发射一个穿透的刀，将经过的我方单位切成两个较小的单位，属性对半分 | F6: 1
A7: 生物 | B7: 人海流 | C7: 生物数量，弹射 | D7: 1 | E7: 我方回合，每次碰到我方单位，对随机敌方造成一次伤害 | F7: 1
A8: 生物 | B8: 人海流 | C8: 生物数量，精英，弹射 | D8: 1 | E8: 吞噬每回合首个碰撞到的我方单位，获得其X%的基础属性
A9: 法术 | B9: 人海流 | C9: 生物数量，精英，穿透 | D9: 2 | E9: 将穿过的所有单位属性变为首个穿过单位的属性，回合结束后恢复
A10: 法术 | B10: 弹射流 | C10: 弹射，时机把控 | D10: 1 | E10: 中子对撞A，打出后速度较慢，碰到中子对撞B时发生大爆炸，造成伤害
A11: 法术 | B11: 弹射流 | C11: 弹射，时机把控 | D11: 1 | E11: 中子对撞B，打出后速度较快，碰到中子对撞A时发生大爆炸，造成伤害
A12: 生物 | B12: 弹射流 | C12: 弹射 | D12: 1 | E12: 单回合内，对同一个单位碰撞多次伤害增加 | F12: 1
A13: 生物 | B13: 弹射流 | C13: 弹射，时机把控 | D13: 1 | E13: 击中位移状态的敌方单位时，伤害增加
A14: 生物 | B14: 弹射流 | C14: 弹射，标记 | D14: 1 | E14: 标记每回合首次碰到的敌人，该敌人受到伤害增加 | F14: 1
A15: 生物 | B15: 弹射流 | C15: 弹射 | D15: 1 | E15: 单回合内，每碰撞一次，攻击增加，回合结束时恢复 | F15: 1
A16: 法术 | B16: 穿透流 | C16: 穿透 | D16: 2 | E16: 初始低伤害，每穿透一个伤害增加 | F16: 1
A17: 法术 | B17: 穿透流 | C17: 穿透，路径 | D17: 2 | E17: 留下路径，若路径闭合则对其中的单位造成大量伤害，回合结束路径消失
A18: 法术 | B18: 穿透流 | C18: 穿透，范围 | D18: 2 | E18: 敌方切分，将经过的敌方单位切成两个较小的单位，属性对半分 | F18: 1
A19: 法术 | B19: 穿透流 | C19: 穿透 | D19: 2 | E19: 分裂箭，每穿透一个单位，分裂成两道箭，最多分裂N次
A20: 法术 | B20: 穿透流 | C20: 穿透 | D20: 2 | E20: 借力打力，对经过的第二个单位，造成第一个单位攻击力的伤害 | F20: 1
A21: 法术 | B21: 穿透流 | C21: 穿透，标记 | D21: 2 | E21: 对经过的单位附上XX标记
A22: 法术 | B22: 穿透流 | C22: 穿透，链接 | D22: 2 | E22: 按顺序链接经过的单位
A23: 法术 | B23: 穿透流 | C23: 穿透，链接 | D23: 2 | E23: 穿过链接线时对链接的单位造成伤害
A24: 生物 | B24: 英雄流 | C24: 英雄，标记 | D24: 1 | E24: 标记碰撞的首个敌方单位，回合结束时，我方英雄向其位移 | F24: 1
A25: 生物 | B25: 英雄流 | C25: 英雄，弹射 | D25: 1 | E25: 碰到英雄后，获得属性加成 | F25: 1
A26: 生物 | B26: 英雄流 | C26: 英雄，亡语 | D26: 1 | E26: 该单位死亡时，为英雄增加攻击力 | F26: 1
A27: 生物 | B27: 英雄流 | C27: 英雄，弹射 | D27: 1 | E27: 每回合首次碰撞英雄时，对施加一个较大的力 | F27: 1
A28: 生物 | B28: 英雄流 | C28: 英雄，弹射，亡语 | D28: 1 | E28: 碰到我方英雄，使该生物牺牲，将属性按比例加到英雄上 | F28: 1
A29: 法术 | B29: 英雄流 | C29: 英雄，穿透，燃血 | D29: 2 | E29: 牺牲穿过的我方单位，将其属性按比例加到英雄上 | F29: 1
A30: 法术 | B30: 英雄流 | C30: 英雄，弹射 | D30: 2 | E30: 打出时，英雄按同一个方向进行位移 | F30: 1
A31: 生物 | B31: 过牌流 | C31: 过牌，燃血 | D31: 1 | E31: 每回合燃烧英雄血量，进行抽牌 | F31: 1
A32: 生物 | B32: 过牌流 | C32: 过牌 | D32: 1 | E32: 每回合生成一张临时牌
A33: 生物 | B33: 过牌流 | C33: 过牌，击杀，精英 | D33: 1 | E33: 该生物每击杀一个敌人，我方英雄增加N点能量 | F33: 1
A34: 生物 | B34: 过牌流 | C34: 生物数量，弹射，过牌 | D34: 1 | E34: 我方回合，首次碰撞敌方英雄时，生成一张临时该卡，场上最多存在N个 | F34: 1
A35: 生物 | B35: 通用 | C35: 过牌 | D35: 1 | E35: 连发增幅系列，例如连续打出三张同名卡，则获得X收益 | F35: 1
A36: 法术 | B36: 通用 | C36: 牌序，弹射 | D36: 3 | E36: 加速器，下一张打出的卡牌，发射速度增加 | F36: 2
A37: 法术 | B37: 通用 | C37: 牌序 | D37: 3 | E37: 减速力场，下一张打出的卡牌，发射速度减少，摩擦力也降低
A38: 法术 | B38: 通用 | C38: 牌序 | D38: 3 | E38: 连发步枪，间隔一小段时间，连续打出后两张卡牌
A39: 法术 | B39: 通用 | C39: 弹射 | D39: 2 | E39: 单位控制器，释放时，攻击最高的单位按释放方向进行移动 | F39: 1
A40: 法术 | B40: 通用 | C40: 穿透 | D40: 2 | E40: 通用穿透，每穿透一个单位伤害减少 | F40: 1
...

Sheet AI阵容搭配规划
A1: bot_type | B1: hero_id | D1: card_list | Q1: ##var | R1: id | S1: bot_type | T1: hero_id | U1: card_list
A2: int | B2: int | D2: list,int | Q2: ##type | R2: int | S2: int | T2: int | U2: list,int
A3: ai类型 | B3: 英雄id | D3: 卡组 | Q3: ## | R3: id | S3: ai类型 | T3: 英雄id | U3: 卡组
A4: s | B4: s | D4: s | Q4: ##group | S4: s | T4: s | U4: s
A5: 0 | B5: 10000 | C5: 卡组ID | D5: 10021 | E5: 10030 | F5: 10080 | G5: 10036 | H5: 10035 | I5: 10037 | J5: 10012 | K5: 10031 | L5: 10026 | M5: 10020
B6: =IF(ISNUMBER(MATCH(B5,单位卡分表!$N:$N,0)),INDEX(单位卡分表!$B:$B,MATCH(B5,单位卡分表!$N:$N,0)),INDEX(技能卡分表!$B:$B,MATCH(B5,技能卡分表!$A:$A,0))) -> 传奇飞行员 舰长 | C6: 名字 | D6: =IF(ISNUMBER(MATCH(D5,单位卡分表!$A:$A,0)),INDEX(单位卡分表!$B:$B,MATCH(D5,单位卡分表!$A:$A,0)),INDEX(技能卡分表!$B:$B,MATCH(D5,技能卡分表!$A:$A,0))) -> 自动铅笔 追忆 | E6: =IF(ISNUMBER(MATCH(E5,单位卡分表!$A:$A,0)),INDEX(单位卡分表!$B:$B,MATCH(E5,单位卡分表!$A:$A,0)),INDEX(技能卡分表!$B:$B,MATCH(E5,技能卡分表!$A:$A,0))) -> 军鼓 震声 | F6: =IF(ISNUMBER(MATCH(F5,单位卡分表!$A:$A,0)),INDEX(单位卡分表!$B:$B,MATCH(F5,单位卡分表!$A:$A,0)),INDEX(技能卡分表!$B:$B,MATCH(F5,技能卡分表!$A:$A,0))) -> 安全帽 小橘 | G6: =IF(ISNUMBER(MATCH(G5,单位卡分表!$A:$A,0)),INDEX(单位卡分表!$B:$B,MATCH(G5,单位卡分表!$A:$A,0)),INDEX(技能卡分表!$B:$B,MATCH(G5,技能卡分表!$A:$A,0))) -> 纯净水 满满 | H6: =IF(ISNUMBER(MATCH(H5,单位卡分表!$A:$A,0)),INDEX(单位卡分表!$B:$B,MATCH(H5,单位卡分表!$A:$A,0)),INDEX(技能卡分表!$B:$B,MATCH(H5,技能卡分表!$A:$A,0))) -> 纯净水 浅浅 | I6: =IF(ISNUMBER(MATCH(I5,单位卡分表!$A:$A,0)),INDEX(单位卡分表!$B:$B,MATCH(I5,单位卡分表!$A:$A,0)),INDEX(技能卡分表!$B:$B,MATCH(I5,技能卡分表!$A:$A,0))) -> 红汽水 浅浅 | J6: =IF(ISNUMBER(MATCH(J5,单位卡分表!$A:$A,0)),INDEX(单位卡分表!$B:$B,MATCH(J5,单位卡分表!$A:$A,0)),INDEX(技能卡分表!$B:$B,MATCH(J5,技能卡分表!$A:$A,0))) -> 摩托 赤狸 塞琳娜 | K6: =IF(ISNUMBER(MATCH(K5,单位卡分表!$A:$A,0)),INDEX(单位卡分表!$B:$B,MATCH(K5,单位卡分表!$A:$A,0)),INDEX(技能卡分表!$B:$B,MATCH(K5,技能卡分表!$A:$A,0))) -> 注射器 针妮 佩妮（英文penny，联想小针） | ... M6: =IF(ISNUMBER(MATCH(M5,单位卡分表!$A:$A,0)),INDEX(单位卡分表!$B:$B,MATCH(M5,单位卡分表!$A:$A,0)),INDEX(技能卡分表!$B:$B,MATCH(M5,技能卡分表!$A:$A,0))) -> 时钟 晨曦 | N6: =IF(SUMPRODUCT(COUNTIF(D6:M6,D6:M6))>COLUMNS(D6:M6),"有重复","无重复") -> 无重复
A7: 0 | B7: 10000 | C7: 卡组ID | D7: 10039 | E7: 10030 | F7: 10050 | G7: 10036 | H7: 10035 | I7: 10037 | J7: 10079 | K7: 10044 | L7: 10026 | M7: 10020
